Workbook

Sheet Summary
B1: AR & AP Audit Sampling – Summary
B3: INPUTS
B4: Population basis (toggle) | C4: By ledger | D4: By ledger = AR population (AR file) and AP population (AP file), each tested on its own. By side = AR + Supplier Advances vs AP + Customer Advances.
B5: Materiality (SR) | C5: 10000 | D5: Provided by user (10,000). Book1.xlsx shows 500 (header) and 4,000 (calculated) – not used.
B6: Confidence factor (toggle: 0.5 / 0.75 / 1) | C6: 0.5 | D6: ="Sampling interval = materiality ÷ confidence factor = "&TEXT($C$5/$C$6,"#,##0.00") -> Sampling interval = materiality ÷ confidence factor = 20,000.00
B7: Required n – Population 1 (AR + Supplier Advances) | C7: =IF($C$18=0,0,MIN($C$18,MAX(1,ROUND($C$19/($C$5/$C$6),0)))) -> 9 | D7: ="Calculated: ROUND(below-materiality value "&TEXT($C$19,"#,##0.00")&" ÷ interval) – no risk-level cap" -> Calculated: ROUND(below-materiality value 185,567.52 ÷ interval) – no risk-level cap
B8: Required n – Population 2 (AP + Customer Advances) | C8: =IF($D$18=0,0,MIN($D$18,MAX(1,ROUND($D$19/($C$5/$C$6),0)))) -> 1 | D8: ="Calculated: ROUND(below-materiality value "&TEXT($D$19,"#,##0.00")&" ÷ interval) – no risk-level cap" -> Calculated: ROUND(below-materiality value 13,344.30 ÷ interval) – no risk-level cap
B9: Below-materiality selection method (toggle) | C9: Highest value | D9: Highest value = the n largest below-materiality accounts (default). Random = random number, sorted high to low, top n.
B10: Random seed (kept for the Random option) | C10: 9590851565024595472 | D10: One independent random draw per non-nil party; stored as fixed values (Population, column T).
B11: SAMPLING SUMMARY
B12: Particular | C12: =IF($C$4="By ledger","AR Population (AR file: receivables + customer advances)","Receivable Side (AR + Supplier Advances)") -> AR Population (AR file: receivables + customer advances) | D12: =IF($C$4="By ledger","AP Population (AP file: payables + supplier advances)","Payable Side (AP + Customer Advances)") -> AP Population (AP file: payables + supplier advances)
B13: Materiality | C13: =$C$5 -> 10000 | D13: =$C$5 -> 10000
B14: Total population (items) | C14: =COUNTIFS(Population!$O$2:$O$1092,"Population 1") -> 115 | D14: =COUNTIFS(Population!$O$2:$O$1092,"Population 2") -> 13
B15: Total population value (absolute, SR) | C15: =SUMIFS(Population!$M$2:$M$1092,Population!$O$2:$O$1092,"Population 1") -> 1364773.6 | D15: =SUMIFS(Population!$M$2:$M$1092,Population!$O$2:$O$1092,"Population 2") -> 326289.5
B16: Above-materiality transactions | C16: =COUNTIFS(Population!$O$2:$O$1092,"Population 1",Population!$P$2:$P$1092,"Above Materiality") -> 37 | D16: =COUNTIFS(Population!$O$2:$O$1092,"Population 2",Population!$P$2:$P$1092,"Above Materiality") -> 4
B17: Above-materiality samples selected | C17: =COUNT('1_P1 Above'!$L$5:$L$154) -> 37 | D17: =COUNT('3_P2 Above'!$L$5:$L$154) -> 4
B18: Below-materiality population (items) | C18: =COUNTIFS(Population!$O$2:$O$1092,"Population 1",Population!$P$2:$P$1092,"Below Materiality") -> 78 | D18: =COUNTIFS(Population!$O$2:$O$1092,"Population 2",Population!$P$2:$P$1092,"Below Materiality") -> 9
B19: Below-materiality population value (absolute, SR) | C19: =SUMIFS(Population!$M$2:$M$1092,Population!$O$2:$O$1092,"Population 1",Population!$P$2:$P$1092,"Below Materiality") -> 185567.52 | D19: =SUMIFS(Population!$M$2:$M$1092,Population!$O$2:$O$1092,"Population 2",Population!$P$2:$P$1092,"Below Materiality") -> 13344.3
B20: Required below-materiality sample size (n) | C20: =$C$7 -> 9 | D20: =$C$8 -> 1
B21: Below-materiality samples selected | C21: =COUNT('2_P1 Below Sample'!$L$5:$L$104) -> 9 | D21: =COUNT('4_P2 Below Sample'!$L$5:$L$104) -> 1
B23: COMPOSITION OF THE POPULATIONS (by source ledger)
B24: Source ledger | C24: Parties (items) | D24: Value (absolute, SR) | E24: Population
B25: Accounts Receivable | C25: =COUNTIFS(Population!$N$2:$N$1092,B25) -> 85 | D25: =SUMIFS(Population!$M$2:$M$1092,Population!$N$2:$N$1092,B25) -> 1214371.3 | E25: ="Population 1" -> Population 1 | F25: AR file, positive closing balance
B26: Supplier Advances | C26: =COUNTIFS(Population!$N$2:$N$1092,B26) -> 5 | D26: =SUMIFS(Population!$M$2:$M$1092,Population!$N$2:$N$1092,B26) -> 178340 | E26: =IF($C$4="By ledger","Population 2","Population 1") -> Population 2 | F26: AP file, positive closing balance (debit)
B27: Accounts Payable | C27: =COUNTIFS(Population!$N$2:$N$1092,B27) -> 8 | D27: =SUMIFS(Population!$M$2:$M$1092,Population!$N$2:$N$1092,B27) -> 147949.5 | E27: ="Population 2" -> Population 2 | F27: AP file, negative closing balance (credit)
B28: Customer Advances | C28: =COUNTIFS(Population!$N$2:$N$1092,B28) -> 30 | D28: =SUMIFS(Population!$M$2:$M$1092,Population!$N$2:$N$1092,B28) -> 150402.3 | E28: =IF($C$4="By ledger","Population 1","Population 2") -> Population 1 | F28: AR file, negative closing balance (credit)
B29: Nil closing balance (excluded – see sheet) | C29: =COUNTIFS(Population!$N$2:$N$1092,"Nil balance") -> 963 | D29: 0 | E29: Excluded
B31: NOTES
B32: Basis: no transaction-level ledgers exist, so each party's CLOSING BALANCE is one population item (Original Amount = signed closing balance; Absolute Amount = ABS).
B33: Sign convention (per user): AR file positive = receivable, negative = customer advance; AP file negative = payable, positive = supplier advance.
B34: =IF($C$4="By ledger","Population 1 = AR file (receivables + customer advances). Population 2 = AP file (payables + supplier advances). Tested separately, never combined.","Population 1 = AR + Supplier Advances (debit balances). Population 2 = AP + Customer Advances (credit balances). Never combined.") -> Population 1 = AR file (receivables + customer advances). Population 2 = AP file (payables + supplier advances). Tested separately, never combined.
B35: Reference Number, Date and Ledger Code are blank: the source files are party-wise totals and carry none of them. Source file and row are shown for traceability.
B36: Sample size n = ROUND(below-materiality population value ÷ (materiality ÷ confidence factor)), per population; no risk-level cap. Confidence factor toggle is in C6 (0.5 / 0.75 / 1).
B37: Below-materiality selection: default is the n HIGHEST-VALUE accounts (ranked by Absolute Amount). Switch C9 to Random for random-number selection.

Sheet Population
A1: No. | B1: Reference Number | C1: Date | D1: Ledger Code | E1: Ledger Name | F1: Particulars | G1: Source File | H1: Source Row | I1: Opening | J1: Debit | K1: Credit | L1: Original Amount (Closing) | M1: Absolute Amount | N1: Source Ledger | O1: Population | P1: Selection Category | Q1: Random Number (below-materiality only) | R1: Above rank | S1: Selection rank | T1: Stored random draw | U1: Key – above | V1: Key – selection
A2: 1 | E2: HAN S LASER SMART EQUIPMENT GROUP CO.LTD [CHINA] | F2: Party-wise closing balance (Opening 0.00; Debit 177,190.20; Credit 0.00) | G2: AP file | H2: 90 | I2: 0 | J2: 177190.2 | K2: 0 | L2: 177190.2 | M2: =ABS(L2) -> 177190.2 | N2: =IF(L2=0,"Nil balance",IF(G2="AR file",IF(L2>0,"Accounts Receivable","Customer Advances"),IF(L2<0,"Accounts Payable","Supplier Advances"))) -> Supplier Advances | O2: =IF(L2=0,"Excluded",IF(Summary!$C$4="By ledger",IF(G2="AR file","Population 1","Population 2"),IF(L2>0,"Population 1","Population 2"))) -> Population 2 | P2: =IF(O2="Excluded","Excluded – nil closing balance",IF(M2>Summary!$C$5,"Above Materiality","Below Materiality")) -> Above Materiality | Q2: =IF(P2="Below Materiality",T2,"") | R2: =IF(P2="Above Materiality",COUNTIFS($O$2:$O$1092,O2,$P$2:$P$1092,"Above Materiality",$M$2:$M$1092,">"&M2)+COUNTIFS($O$2:$O$1092,O2,$P$2:$P$1092,"Above Materiality",$M$2:$M$1092,M2,$A$2:$A$1092,"<"&A2)+1,"") -> 1 | S2: =IF(P2<>"Below Materiality","",IF(Summary!$C$9="Random",COUNTIFS($O$2:$O$1092,O2,$Q$2:$Q$1092,">"&Q2)+1,COUNTIFS($O$2:$O$1092,O2,$P$2:$P$1092,"Below Materiality",$M$2:$M$1092,">"&M2)+COUNTIFS($O$2:$O$1092,O2,$P$2:$P$1092,"Below Materiality",$M$2:$M$1092,M2,$A$2:$A$1092,"<"&A2)+1)) | T2: 0.98773089 | U2: =IF(R2="","",O2&"|A|"&R2) -> Population 2|A|1 | V2: =IF(S2="","",O2&"|R|"&S2)
A3: 2 | E3: ERAM POWER ELECTRONICS COMPANY | F3: Party-wise closing balance (Opening 275,982.75; Debit 955,512.58; Credit 1,129,685.18) | G3: AR file | H3: 409 | I3: 275982.75 | J3: 955512.58 | K3: 1129685.2 | L3: 101810.15 | M3: =ABS(L3) -> 101810.15 | N3: =IF(L3=0,"Nil balance",IF(G3="AR file",IF(L3>0,"Accounts Receivable","Customer Advances"),IF(L3<0,"Accounts Payable","Supplier Advances"))) -> Accounts Receivable | O3: =IF(L3=0,"Excluded",IF(Summary!$C$4="By ledger",IF(G3="AR file","Population 1","Population 2"),IF(L3>0,"Population 1","Population 2"))) -> Population 1 | P3: =IF(O3="Excluded","Excluded – nil closing balance",IF(M3>Summary!$C$5,"Above Materiality","Below Materiality")) -> Above Materiality | Q3: =IF(P3="Below Materiality",T3,"") | R3: =IF(P3="Above Materiality",COUNTIFS($O$2:$O$1092,O3,$P$2:$P$1092,"Above Materiality",$M$2:$M$1092,">"&M3)+COUNTIFS($O$2:$O$1092,O3,$P$2:$P$1092,"Above Materiality",$M$2:$M$1092,M3,$A$2:$A$1092,"<"&A3)+1,"") -> 1 | S3: =IF(P3<>"Below Materiality","",IF(Summary!$C$9="Random",COUNTIFS($O$2:$O$1092,O3,$Q$2:$Q$1092,">"&Q3)+1,COUNTIFS($O$2:$O$1092,O3,$P$2:$P$1092,"Below Materiality",$M$2:$M$1092,">"&M3)+COUNTIFS($O$2:$O$1092,O3,$P$2:$P$1092,"Below Materiality",$M$2:$M$1092,M3,$A$2:$A$1092,"<"&A3)+1)) | T3: 0.78932792 | U3: =IF(R3="","",O3&"|A|"&R3) -> Population 1|A|1 | V3: =IF(S3="","",O3&"|R|"&S3)
A4: 3 | E4: KHALID GENERAL CONTRACTING CO. | F4: Party-wise closing balance (Opening 90,920.30; Debit 2,081.50; Credit 2,081.50) | G4: AR file | H4: 276 | I4: 90920.3 | J4: 2081.5 | K4: 2081.5 | L4: 90920.3 | M4: =ABS(L4) -> 90920.3 | N4: =IF(L4=0,"Nil balance",IF(G4="AR file",IF(L4>0,"Accounts Receivable","Customer Advances"),IF(L4<0,"Accounts Payable","Supplier Advances"))) -> Accounts Receivable | O4: =IF(L4=0,"Excluded",IF(Summary!$C$4="By ledger",IF(G4="AR file","Population 1","Population 2"),IF(L4>0,"Population 1","Population 2"))) -> Population 1 | P4: =IF(O4="Excluded","Excluded – nil closing balance",IF(M4>Summary!$C$5,"Above Materiality","Below Materiality")) -> Above Materiality | Q4: =IF(P4="Below Materiality",T4,"") | R4: =IF(P4="Above Materiality",COUNTIFS($O$2:$O$1092,O4,$P$2:$P$1092,"Above Materiality",$M$2:$M$1092,">"&M4)+COUNTIFS($O$2:$O$1092,O4,$P$2:$P$1092,"Above Materiality",$M$2:$M$1092,M4,$A$2:$A$1092,"<"&A4)+1,"") -> 2 | S4: =IF(P4<>"Below Materiality","",IF(Summary!$C$9="Random",COUNTIFS($O$2:$O$1092,O4,$Q$2:$Q$1092,">"&Q4)+1,COUNTIFS($O$2:$O$1092,O4,$P$2:$P$1092,"Below Materiality",$M$2:$M$1092,">"&M4)+COUNTIFS($O$2:$O$1092,O4,$P$2:$P$1092,"Below Materiality",$M$2:$M$1092,M4,$A$2:$A$1092,"<"&A4)+1)) | T4: 0.2390787 | U4: =IF(R4="","",O4&"|A|"&R4) -> Population 1|A|2 | V4: =IF(S4="","",O4&"|R|"&S4)
A5: 4 | E5: SIGN CITY TRADING COMPANY | F5: Party-wise closing balance (Opening 0.00; Debit 153,563.00; Credit 225,737.00) | G5: AP file | H5: 161 | I5: 0 | J5: 153563 | K5: 225737 | L5: -72174 | M5: =ABS(L5) -> 72174 | N5: =IF(L5=0,"Nil balance",IF(G5="AR file",IF(L5>0,"Accounts Receivable","Customer Advances"),IF(L5<0,"Accounts Payable","Supplier Advances"))) -> Accounts Payable | O5: =IF(L5=0,"Excluded",IF(Summary!$C$4="By ledger",IF(G5="AR file","Population 1","Population 2"),IF(L5>0,"Population 1","Population 2"))) -> Population 2 | P5: =IF(O5="Excluded","Excluded – nil closing balance",IF(M5>Summary!$C$5,"Above Materiality","Below Materiality")) -> Above Materiality | Q5: =IF(P5="Below Materiality",T5,"") | R5: =IF(P5="Above Materiality",COUNTIFS($O$2:$O$1092,O5,$P$2:$P$1092,"Above Materiality",$M$2:$M$1092,">"&M5)+COUNTIFS($O$2:$O$1092,O5,$P$2:$P$1092,"Above Materiality",$M$2:$M$1092,M5,$A$2:$A$1092,"<"&A5)+1,"") -> 2 | S5: =IF(P5<>"Below Materiality","",IF(Summary!$C$9="Random",COUNTIFS($O$2:$O$1092,O5,$Q$2:$Q$1092,">"&Q5)+1,COUNTIFS($O$2:$O$1092,O5,$P$2:$P$1092,"Below Materiality",$M$2:$M$1092,">"&M5)+COUNTIFS($O$2:$O$1092,O5,$P$2:$P$1092,"Below Materiality",$M$2:$M$1092,M5,$A$2:$A$1092,"<"&A5)+1)) | T5: 0.39511056 | U5: =IF(R5="","",O5&"|A|"&R5) -> Population 2|A|2 | V5: =IF(S5="","",O5&"|R|"&S5)
A6: 5 | E6: KHALID INDUSTRIAL MARBLE FACTORY | F6: Party-wise closing balance (Opening 58,002.75; Debit 0.00; Credit 0.00) | G6: AR file | H6: 16 | I6: 58002.75 | J6: 0 | K6: 0 | L6: 58002.75 | M6: =ABS(L6) -> 58002.75 | N6: =IF(L6=0,"Nil balance",IF(G6="AR file",IF(L6>0,"Accounts Receivable","Customer Advances"),IF(L6<0,"Accounts Payable","Supplier Advances"))) -> Accounts Receivable | O6: =IF(L6=0,"Excluded",IF(Summary!$C$4="By ledger",IF(G6="AR file","Population 1","Population 2"),IF(L6>0,"Population 1","Population 2"))) -> Population 1 | P6: =IF(O6="Excluded","Excluded – nil closing balance",IF(M6>Summary!$C$5,"Above Materiality","Below Materiality")) -> Above Materiality | Q6: =IF(P6="Below Materiality",T6,"") | R6: =IF(P6="Above Materiality",COUNTIFS($O$2:$O$1092,O6,$P$2:$P$1092,"Above Materiality",$M$2:$M$1092,">"&M6)+COUNTIFS($O$2:$O$1092,O6,$P$2:$P$1092,"Above Materiality",$M$2:$M$1092,M6,$A$2:$A$1092,"<"&A6)+1,"") -> 3 | S6: =IF(P6<>"Below Materiality","",IF(Summary!$C$9="Random",COUNTIFS($O$2:$O$1092,O6,$Q$2:$Q$1092,">"&Q6)+1,COUNTIFS($O$2:$O$1092,O6,$P$2:$P$1092,"Below Materiality",$M$2:$M$1092,">"&M6)+COUNTIFS($O$2:$O$1092,O6,$P$2:$P$1092,"Below Materiality",$M$2:$M$1092,M6,$A$2:$A$1092,"<"&A6)+1)) | T6: 0.20318976 | U6: =IF(R6="","",O6&"|A|"&R6) -> Population 1|A|3 | V6: =IF(S6="","",O6&"|R|"&S6)
A7: 6 | E7: EASTERN SOURCES COMPANY FOR ENERGY AND INDUSTRIAL COMMERCIAL SERVICES | F7: Party-wise closing balance (Opening 0.00; Debit 59,641.88; Credit 2,199.38) | G7: AR file | H7: 857 | I7: 0 | J7: 59641.88 | K7: 2199.38 | L7: 57442.5 | M7: =ABS(L7) -> 57442.5 | N7: =IF(L7=0,"Nil balance",IF(G7="AR file",IF(L7>0,"Accounts Receivable","Customer Advances"),IF(L7<0,"Accounts Payable","Supplier Advances"))) -> Accounts Receivable | O7: =IF(L7=0,"Excluded",IF(Summary!$C$4="By ledger",IF(G7="AR file","Population 1","Population 2"),IF(L7>0,"Population 1","Population 2"))) -> Population 1 | P7: =IF(O7="Excluded","Excluded – nil closing balance",IF(M7>Summary!$C$5,"Above Materiality","Below Materiality")) -> Above Materiality | Q7: =IF(P7="Below Materiality",T7,"") | R7: =IF(P7="Above Materiality",COUNTIFS($O$2:$O$1092,O7,$P$2:$P$1092,"Above Materiality",$M$2:$M$1092,">"&M7)+COUNTIFS($O$2:$O$1092,O7,$P$2:$P$1092,"Above Materiality",$M$2:$M$1092,M7,$A$2:$A$1092,"<"&A7)+1,"") -> 4 | S7: =IF(P7<>"Below Materiality","",IF(Summary!$C$9="Random",COUNTIFS($O$2:$O$1092,O7,$Q$2:$Q$1092,">"&Q7)+1,COUNTIFS($O$2:$O$1092,O7,$P$2:$P$1092,"Below Materiality",$M$2:$M$1092,">"&M7)+COUNTIFS($O$2:$O$1092,O7,$P$2:$P$1092,"Below Materiality",$M$2:$M$1092,M7,$A$2:$A$1092,"<"&A7)+1)) | T7: 0.73573583 | U7: =IF(R7="","",O7&"|A|"&R7) -> Population 1|A|4 | V7: =IF(S7="","",O7&"|R|"&S7)
A8: 7 | E8: JUMEIRAH TRADING COMPANY LIMITED | F8: Party-wise closing balance (Opening 0.00; Debit 56,892.80; Credit 772.80) | G8: AR file | H8: 478 | I8: 0 | J8: 56892.8 | K8: 772.8 | L8: 56120 | M8: =ABS(L8) -> 56120 | N8: =IF(L8=0,"Nil balance",IF(G8="AR file",IF(L8>0,"Accounts Receivable","Customer Advances"),IF(L8<0,"Accounts Payable","Supplier Advances"))) -> Accounts Receivable | O8: =IF(L8=0,"Excluded",IF(Summary!$C$4="By ledger",IF(G8="AR file","Population 1","Population 2"),IF(L8>0,"Population 1","Population 2"))) -> Population 1 | P8: =IF(O8="Excluded","Excluded – nil closing balance",IF(M8>Summary!$C$5,"Above Materiality","Below Materiality")) -> Above Materiality | Q8: =IF(P8="Below Materiality",T8,"") | R8: =IF(P8="Above Materiality",COUNTIFS($O$2:$O$1092,O8,$P$2:$P$1092,"Above Materiality",$M$2:$M$1092,">"&M8)+COUNTIFS($O$2:$O$1092,O8,$P$2:$P$1092,"Above Materiality",$M$2:$M$1092,M8,$A$2:$A$1092,"<"&A8)+1,"") -> 5 | S8: =IF(P8<>"Below Materiality","",IF(Summary!$C$9="Random",COUNTIFS($O$2:$O$1092,O8,$Q$2:$Q$1092,">"&Q8)+1,COUNTIFS($O$2:$O$1092,O8,$P$2:$P$1092,"Below Materiality",$M$2:$M$1092,">"&M8)+COUNTIFS($O$2:$O$1092,O8,$P$2:$P$1092,"Below Materiality",$M$2:$M$1092,M8,$A$2:$A$1092,"<"&A8)+1)) | T8: 0.43079415 | U8: =IF(R8="","",O8&"|A|"&R8) -> Population 1|A|5 | V8: =IF(S8="","",O8&"|R|"&S8)
A9: 8 | E9: FAB MODERN INDUSTRY CO. | F9: Party-wise closing balance (Opening 28,188.06; Debit 27,128.50; Credit 4,150.00) | G9: AR file | H9: 216 | I9: 28188.06 | J9: 27128.5 | K9: 4150 | L9: 51166.56 | M9: =ABS(L9) -> 51166.56 | N9: =IF(L9=0,"Nil balance",IF(G9="AR file",IF(L9>0,"Accounts Receivable","Customer Advances"),IF(L9<0,"Accounts Payable","Supplier Advances"))) -> Accounts Receivable | O9: =IF(L9=0,"Excluded",IF(Summary!$C$4="By ledger",IF(G9="AR file","Population 1","Population 2"),IF(L9>0,"Population 1","Population 2"))) -> Population 1 | P9: =IF(O9="Excluded","Excluded – nil closing balance",IF(M9>Summary!$C$5,"Above Materiality","Below Materiality")) -> Above Materiality | Q9: =IF(P9="Below Materiality",T9,"") | R9: =IF(P9="Above Materiality",COUNTIFS($O$2:$O$1092,O9,$P$2:$P$1092,"Above Materiality",$M$2:$M$1092,">"&M9)+COUNTIFS($O$2:$O$1092,O9,$P$2:$P$1092,"Above Materiality",$M$2:$M$1092,M9,$A$2:$A$1092,"<"&A9)+1,"") -> 6 | S9: =IF(P9<>"Below Materiality","",IF(Summary!$C$9="Random",COUNTIFS($O$2:$O$1092,O9,$Q$2:$Q$1092,">"&Q9)+1,COUNTIFS($O$2:$O$1092,O9,$P$2:$P$1092,"Below Materiality",$M$2:$M$1092,">"&M9)+COUNTIFS($O$2:$O$1092,O9,$P$2:$P$1092,"Below Materiality",$M$2:$M$1092,M9,$A$2:$A$1092,"<"&A9)+1)) | T9: 0.95372432 | U9: =IF(R9="","",O9&"|A|"&R9) -> Population 1|A|6 | V9: =IF(S9="","",O9&"|R|"&S9)
A10: 9 | E10: THE GLOBAL COMPANY FOR MODERN PRINTING & COPYING | F10: Party-wise closing balance (Opening 0.00; Debit 22,333.00; Credit 69,036.00) | G10: AR file | H10: 51 | I10: 0 | J10: 22333 | K10: 69036 | L10: -46703 | M10: =ABS(L10) -> 46703 | N10: =IF(L10=0,"Nil balance",IF(G10="AR file",IF(L10>0,"Accounts Receivable","Customer Advances"),IF(L10<0,"Accounts Payable","Supplier Advances"))) -> Customer Advances | O10: =IF(L10=0,"Excluded",IF(Summary!$C$4="By ledger",IF(G10="AR file","Population 1","Population 2"),IF(L10>0,"Population 1","Population 2"))) -> Population 1 | P10: =IF(O10="Excluded","Excluded – nil closing balance",IF(M10>Summary!$C$5,"Above Materiality","Below Materiality")) -> Above Materiality | Q10: =IF(P10="Below Materiality",T10,"") | R10: =IF(P10="Above Materiality",COUNTIFS($O$2:$O$1092,O10,$P$2:$P$1092,"Above Materiality",$M$2:$M$1092,">"&M10)+COUNTIFS($O$2:$O$1092,O10,$P$2:$P$1092,"Above Materiality",$M$2:$M$1092,M10,$A$2:$A$1092,"<"&A10)+1,"") -> 7 | S10: =IF(P10<>"Below Materiality","",IF(Summary!$C$9="Random",COUNTIFS($O$2:$O$1092,O10,$Q$2:$Q$1092,">"&Q10)+1,COUNTIFS($O$2:$O$1092,O10,$P$2:$P$1092,"Below Materiality",$M$2:$M$1092,">"&M10)+COUNTIFS($O$2:$O$1092,O10,$P$2:$P$1092,"Below Materiality",$M$2:$M$1092,M10,$A$2:$A$1092,"<"&A10)+1)) | T10: 0.20831184 | U10: =IF(R10="","",O10&"|A|"&R10) -> Population 1|A|7 | V10: =IF(S10="","",O10&"|R|"&S10)
A11: 10 | E11: ERAM FLOORING COMPANY | F11: Party-wise closing balance (Opening 0.00; Debit 80,425.25; Credit 39,600.25) | G11: AR file | H11: 199 | I11: 0 | J11: 80425.25 | K11: 39600.25 | L11: 40825 | M11: =ABS(L11) -> 40825 | N11: =IF(L11=0,"Nil balance",IF(G11="AR file",IF(L11>0,"Accounts Receivable","Customer Advances"),IF(L11<0,"Accounts Payable","Supplier Advances"))) -> Accounts Receivable | O11: =IF(L11=0,"Excluded",IF(Summary!$C$4="By ledger",IF(G11="AR file","Population 1","Population 2"),IF(L11>0,"Population 1","Population 2"))) -> Population 1 | P11: =IF(O11="Excluded","Excluded – nil closing balance",IF(M11>Summary!$C$5,"Above Materiality","Below Materiality")) -> Above Materiality | Q11: =IF(P11="Below Materiality",T11,"") | R11: =IF(P11="Above Materiality",COUNTIFS($O$2:$O$1092,O11,$P$2:$P$1092,"Above Materiality",$M$2:$M$1092,">"&M11)+COUNTIFS($O$2:$O$1092,O11,$P$2:$P$1092,"Above Materiality",$M$2:$M$1092,M11,$A$2:$A$1092,"<"&A11)+1,"") -> 8 | S11: =IF(P11<>"Below Materiality","",IF(Summary!$C$9="Random",COUNTIFS($O$2:$O$1092,O11,$Q$2:$Q$1092,">"&Q11)+1,COUNTIFS($O$2:$O$1092,O11,$P$2:$P$1092,"Below Materiality",$M$2:$M$1092,">"&M11)+COUNTIFS($O$2:$O$1092,O11,$P$2:$P$1092,"Below Materiality",$M$2:$M$1092,M11,$A$2:$A$1092,"<"&A11)+1)) | T11: 0.82985992 | U11: =IF(R11="","",O11&"|A|"&R11) -> Population 1|A|8 | V11: =IF(S11="","",O11&"|R|"&S11)
A12: 11 | E12: FAHAD DILSHAD JAN FACTORY CO. | F12: Party-wise closing balance (Opening 95,070.83; Debit 2,541.50; Credit 56,794.00) | G12: AR file | H12: 156 | I12: 95070.83 | J12: 2541.5 | K12: 56794 | L12: 40818.33 | M12: =ABS(L12) -> 40818.33 | N12: =IF(L12=0,"Nil balance",IF(G12="AR file",IF(L12>0,"Accounts Receivable","Customer Advances"),IF(L12<0,"Accounts Payable","Supplier Advances"))) -> Accounts Receivable | O12: =IF(L12=0,"Excluded",IF(Summary!$C$4="By ledger",IF(G12="AR file","Population 1","Population 2"),IF(L12>0,"Population 1","Population 2"))) -> Population 1 | P12: =IF(O12="Excluded","Excluded – nil closing balance",IF(M12>Summary!$C$5,"Above Materiality","Below Materiality")) -> Above Materiality | Q12: =IF(P12="Below Materiality",T12,"") | R12: =IF(P12="Above Materiality",COUNTIFS($O$2:$O$1092,O12,$P$2:$P$1092,"Above Materiality",$M$2:$M$1092,">"&M12)+COUNTIFS($O$2:$O$1092,O12,$P$2:$P$1092,"Above Materiality",$M$2:$M$1092,M12,$A$2:$A$1092,"<"&A12)+1,"") -> 9 | S12: =IF(P12<>"Below Materiality","",IF(Summary!$C$9="Random",COUNTIFS($O$2:$O$1092,O12,$Q$2:$Q$1092,">"&Q12)+1,COUNTIFS($O$2:$O$1092,O12,$P$2:$P$1092,"Below Materiality",$M$2:$M$1092,">"&M12)+COUNTIFS($O$2:$O$1092,O12,$P$2:$P$1092,"Below Materiality",$M$2:$M$1092,M12,$A$2:$A$1092,"<"&A12)+1)) | T12: 0.99869791 | U12: =IF(R12="","",O12&"|A|"&R12) -> Population 1|A|9 | V12: =IF(S12="","",O12&"|R|"&S12)
A13: 12 | E13: AFAN MIDDLE EAST CO. | F13: Party-wise closing balance (Opening 0.00; Debit 1,060.00; Credit 41,425.00) | G13: AR file | H13: 301 | I13: 0 | J13: 1060 | K13: 41425 | L13: -40365 | M13: =ABS(L13) -> 40365 | N13: =IF(L13=0,"Nil balance",IF(G13="AR file",IF(L13>0,"Accounts Receivable","Customer Advances"),IF(L13<0,"Accounts Payable","Supplier Advances"))) -> Customer Advances | O13: =IF(L13=0,"Excluded",IF(Summary!$C$4="By ledger",IF(G13="AR file","Population 1","Population 2"),IF(L13>0,"Population 1","Population 2"))) -> Population 1 | P13: =IF(O13="Excluded","Excluded – nil closing balance",IF(M13>Summary!$C$5,"Above Materiality","Below Materiality")) -> Above Materiality | Q13: =IF(P13="Below Materiality",T13,"") | R13: =IF(P13="Above Materiality",COUNTIFS($O$2:$O$1092,O13,$P$2:$P$1092,"Above Materiality",$M$2:$M$1092,">"&M13)+COUNTIFS($O$2:$O$1092,O13,$P$2:$P$1092,"Above Materiality",$M$2:$M$1092,M13,$A$2:$A$1092,"<"&A13)+1,"") -> 10 | S13: =IF(P13<>"Below Materiality","",IF(Summary!$C$9="Random",COUNTIFS($O$2:$O$1092,O13,$Q$2:$Q$1092,">"&Q13)+1,COUNTIFS($O$2:$O$1092,O13,$P$2:$P$1092,"Below Materiality",$M$2:$M$1092,">"&M13)+COUNTIFS($O$2:$O$1092,O13,$P$2:$P$1092,"Below Materiality",$M$2:$M$1092,M13,$A$2:$A$1092,"<"&A13)+1)) | T13: 0.099650915 | U13: =IF(R13="","",O13&"|A|"&R13) -> Population 1|A|10 | V13: =IF(S13="","",O13&"|R|"&S13)
... A129: 128 | E129: شركة الرائم للمقاولات | F129: Party-wise closing balance (Opening -0.01; Debit 0.01; Credit 0.00) | G129: AR file | H129: 223 | I129: -0.01 | J129: 0.01 | K129: 0 | L129: 9.0951552e-15 | M129: =ABS(L129) -> 9.0951552e-15 | N129: =IF(L129=0,"Nil balance",IF(G129="AR file",IF(L129>0,"Accounts Receivable","Customer Advances"),IF(L129<0,"Accounts Payable","Supplier Advances"))) -> Accounts Receivable | O129: =IF(L129=0,"Excluded",IF(Summary!$C$4="By ledger",IF(G129="AR file","Population 1","Population 2"),IF(L129>0,"Population 1","Population 2"))) -> Population 1 | P129: =IF(O129="Excluded","Excluded – nil closing balance",IF(M129>Summary!$C$5,"Above Materiality","Below Materiality")) -> Below Materiality | Q129: =IF(P129="Below Materiality",T129,"") -> 0.74053636 | R129: =IF(P129="Above Materiality",COUNTIFS($O$2:$O$1092,O129,$P$2:$P$1092,"Above Materiality",$M$2:$M$1092,">"&M129)+COUNTIFS($O$2:$O$1092,O129,$P$2:$P$1092,"Above Materiality",$M$2:$M$1092,M129,$A$2:$A$1092,"<"&A129)+1,"") | S129: =IF(P129<>"Below Materiality","",IF(Summary!$C$9="Random",COUNTIFS($O$2:$O$1092,O129,$Q$2:$Q$1092,">"&Q129)+1,COUNTIFS($O$2:$O$1092,O129,$P$2:$P$1092,"Below Materiality",$M$2:$M$1092,">"&M129)+COUNTIFS($O$2:$O$1092,O129,$P$2:$P$1092,"Below Materiality",$M$2:$M$1092,M129,$A$2:$A$1092,"<"&A129)+1)) -> 78 | T129: 0.74053636 | U129: =IF(R129="","",O129&"|A|"&R129) | V129: =IF(S129="","",O129&"|R|"&S129) -> Population 1|R|78
A130: 129 | E130: AAMAL AL ARIF TRADING EST | F130: Party-wise closing balance (Opening 0.00; Debit 650.00; Credit 650.00) | G130: AP file | H130: 2 | I130: 0 | J130: 650 | K130: 650 | L130: 0 | M130: =ABS(L130) -> 0 | N130: =IF(L130=0,"Nil balance",IF(G130="AR file",IF(L130>0,"Accounts Receivable","Customer Advances"),IF(L130<0,"Accounts Payable","Supplier Advances"))) -> Nil balance | O130: =IF(L130=0,"Excluded",IF(Summary!$C$4="By ledger",IF(G130="AR file","Population 1","Population 2"),IF(L130>0,"Population 1","Population 2"))) -> Excluded | P130: =IF(O130="Excluded","Excluded – nil closing balance",IF(M130>Summary!$C$5,"Above Materiality","Below Materiality")) -> Excluded – nil closing balance | Q130: =IF(P130="Below Materiality",T130,"") | R130: =IF(P130="Above Materiality",COUNTIFS($O$2:$O$1092,O130,$P$2:$P$1092,"Above Materiality",$M$2:$M$1092,">"&M130)+COUNTIFS($O$2:$O$1092,O130,$P$2:$P$1092,"Above Materiality",$M$2:$M$1092,M130,$A$2:$A$1092,"<"&A130)+1,"") | S130: =IF(P130<>"Below Materiality","",IF(Summary!$C$9="Random",COUNTIFS($O$2:$O$1092,O130,$Q$2:$Q$1092,">"&Q130)+1,COUNTIFS($O$2:$O$1092,O130,$P$2:$P$1092,"Below Materiality",$M$2:$M$1092,">"&M130)+COUNTIFS($O$2:$O$1092,O130,$P$2:$P$1092,"Below Materiality",$M$2:$M$1092,M130,$A$2:$A$1092,"<"&A130)+1)) | U130: =IF(R130="","",O130&"|A|"&R130) | V130: =IF(S130="","",O130&"|R|"&S130)
A131: 130 | E131: ABA HSAIN TRADING GROUP | F131: Party-wise closing balance (Opening 0.00; Debit 7,300.20; Credit 7,300.20) | G131: AP file | H131: 3 | I131: 0 | J131: 7300.2 | K131: 7300.2 | L131: 0 | M131: =ABS(L131) -> 0 | N131: =IF(L131=0,"Nil balance",IF(G131="AR file",IF(L131>0,"Accounts Receivable","Customer Advances"),IF(L131<0,"Accounts Payable","Supplier Advances"))) -> Nil balance | O131: =IF(L131=0,"Excluded",IF(Summary!$C$4="By ledger",IF(G131="AR file","Population 1","Population 2"),IF(L131>0,"Population 1","Population 2"))) -> Excluded | P131: =IF(O131="Excluded","Excluded – nil closing balance",IF(M131>Summary!$C$5,"Above Materiality","Below Materiality")) -> Excluded – nil closing balance | Q131: =IF(P131="Below Materiality",T131,"") | R131: =IF(P131="Above Materiality",COUNTIFS($O$2:$O$1092,O131,$P$2:$P$1092,"Above Materiality",$M$2:$M$1092,">"&M131)+COUNTIFS($O$2:$O$1092,O131,$P$2:$P$1092,"Above Materiality",$M$2:$M$1092,M131,$A$2:$A$1092,"<"&A131)+1,"") | S131: =IF(P131<>"Below Materiality","",IF(Summary!$C$9="Random",COUNTIFS($O$2:$O$1092,O131,$Q$2:$Q$1092,">"&Q131)+1,COUNTIFS($O$2:$O$1092,O131,$P$2:$P$1092,"Below Materiality",$M$2:$M$1092,">"&M131)+COUNTIFS($O$2:$O$1092,O131,$P$2:$P$1092,"Below Materiality",$M$2:$M$1092,M131,$A$2:$A$1092,"<"&A131)+1)) | U131: =IF(R131="","",O131&"|A|"&R131) | V131: =IF(S131="","",O131&"|R|"&S131)
A132: 131 | E132: ABCPA - ASHRAF BASSAS&PARTNERS | F132: Party-wise closing balance (Opening 0.00; Debit 16,675.00; Credit 16,675.00) | G132: AP file | H132: 4 | I132: 0 | J132: 16675 | K132: 16675 | L132: 0 | M132: =ABS(L132) -> 0 | N132: =IF(L132=0,"Nil balance",IF(G132="AR file",IF(L132>0,"Accounts Receivable","Customer Advances"),IF(L132<0,"Accounts Payable","Supplier Advances"))) -> Nil balance | O132: =IF(L132=0,"Excluded",IF(Summary!$C$4="By ledger",IF(G132="AR file","Population 1","Population 2"),IF(L132>0,"Population 1","Population 2"))) -> Excluded | P132: =IF(O132="Excluded","Excluded – nil closing balance",IF(M132>Summary!$C$5,"Above Materiality","Below Materiality")) -> Excluded – nil closing balance | Q132: =IF(P132="Below Materiality",T132,"") | R132: =IF(P132="Above Materiality",COUNTIFS($O$2:$O$1092,O132,$P$2:$P$1092,"Above Materiality",$M$2:$M$1092,">"&M132)+COUNTIFS($O$2:$O$1092,O132,$P$2:$P$1092,"Above Materiality",$M$2:$M$1092,M132,$A$2:$A$1092,"<"&A132)+1,"") | S132: =IF(P132<>"Below Materiality","",IF(Summary!$C$9="Random",COUNTIFS($O$2:$O$1092,O132,$Q$2:$Q$1092,">"&Q132)+1,COUNTIFS($O$2:$O$1092,O132,$P$2:$P$1092,"Below Materiality",$M$2:$M$1092,">"&M132)+COUNTIFS($O$2:$O$1092,O132,$P$2:$P$1092,"Below Materiality",$M$2:$M$1092,M132,$A$2:$A$1092,"<"&A132)+1)) | U132: =IF(R132="","",O132&"|A|"&R132) | V132: =IF(S132="","",O132&"|R|"&S132)
A133: 132 | E133: ABDULLAH TALAB TRADING EST. | F133: Party-wise closing balance (Opening 0.00; Debit 500.00; Credit 500.00) | G133: AP file | H133: 5 | I133: 0 | J133: 500 | K133: 500 | L133: 0 | M133: =ABS(L133) -> 0 | N133: =IF(L133=0,"Nil balance",IF(G133="AR file",IF(L133>0,"Accounts Receivable","Customer Advances"),IF(L133<0,"Accounts Payable","Supplier Advances"))) -> Nil balance | O133: =IF(L133=0,"Excluded",IF(Summary!$C$4="By ledger",IF(G133="AR file","Population 1","Population 2"),IF(L133>0,"Population 1","Population 2"))) -> Excluded | P133: =IF(O133="Excluded","Excluded – nil closing balance",IF(M133>Summary!$C$5,"Above Materiality","Below Materiality")) -> Excluded – nil closing balance | Q133: =IF(P133="Below Materiality",T133,"") | R133: =IF(P133="Above Materiality",COUNTIFS($O$2:$O$1092,O133,$P$2:$P$1092,"Above Materiality",$M$2:$M$1092,">"&M133)+COUNTIFS($O$2:$O$1092,O133,$P$2:$P$1092,"Above Materiality",$M$2:$M$1092,M133,$A$2:$A$1092,"<"&A133)+1,"") | S133: =IF(P133<>"Below Materiality","",IF(Summary!$C$9="Random",COUNTIFS($O$2:$O$1092,O133,$Q$2:$Q$1092,">"&Q133)+1,COUNTIFS($O$2:$O$1092,O133,$P$2:$P$1092,"Below Materiality",$M$2:$M$1092,">"&M133)+COUNTIFS($O$2:$O$1092,O133,$P$2:$P$1092,"Below Materiality",$M$2:$M$1092,M133,$A$2:$A$1092,"<"&A133)+1)) | U133: =IF(R133="","",O133&"|A|"&R133) | V133: =IF(S133="","",O133&"|R|"&S133)
A134: 133 | E134: ABDULLMOHSEN AL MARIQ TRADING EST | F134: Party-wise closing balance (Opening 0.00; Debit 1,030.00; Credit 1,030.00) | G134: AP file | H134: 6 | I134: 0 | J134: 1030 | K134: 1030 | L134: 0 | M134: =ABS(L134) -> 0 | N134: =IF(L134=0,"Nil balance",IF(G134="AR file",IF(L134>0,"Accounts Receivable","Customer Advances"),IF(L134<0,"Accounts Payable","Supplier Advances"))) -> Nil balance | O134: =IF(L134=0,"Excluded",IF(Summary!$C$4="By ledger",IF(G134="AR file","Population 1","Population 2"),IF(L134>0,"Population 1","Population 2"))) -> Excluded | P134: =IF(O134="Excluded","Excluded – nil closing balance",IF(M134>Summary!$C$5,"Above Materiality","Below Materiality")) -> Excluded – nil closing balance | Q134: =IF(P134="Below Materiality",T134,"") | R134: =IF(P134="Above Materiality",COUNTIFS($O$2:$O$1092,O134,$P$2:$P$1092,"Above Materiality",$M$2:$M$1092,">"&M134)+COUNTIFS($O$2:$O$1092,O134,$P$2:$P$1092,"Above Materiality",$M$2:$M$1092,M134,$A$2:$A$1092,"<"&A134)+1,"") | S134: =IF(P134<>"Below Materiality","",IF(Summary!$C$9="Random",COUNTIFS($O$2:$O$1092,O134,$Q$2:$Q$1092,">"&Q134)+1,COUNTIFS($O$2:$O$1092,O134,$P$2:$P$1092,"Below Materiality",$M$2:$M$1092,">"&M134)+COUNTIFS($O$2:$O$1092,O134,$P$2:$P$1092,"Below Materiality",$M$2:$M$1092,M134,$A$2:$A$1092,"<"&A134)+1)) | U134: =IF(R134="","",O134&"|A|"&R134) | V134: =IF(S134="","",O134&"|R|"&S134)
A135: 134 | E135: ABSOLUTE SOLUTION COMPANY FOR IRON | F135: Party-wise closing balance (Opening 0.00; Debit 6,613.45; Credit 6,613.45) | G135: AP file | H135: 7 | I135: 0 | J135: 6613.45 | K135: 6613.45 | L135: 0 | M135: =ABS(L135) -> 0 | N135: =IF(L135=0,"Nil balance",IF(G135="AR file",IF(L135>0,"Accounts Receivable","Customer Advances"),IF(L135<0,"Accounts Payable","Supplier Advances"))) -> Nil balance | O135: =IF(L135=0,"Excluded",IF(Summary!$C$4="By ledger",IF(G135="AR file","Population 1","Population 2"),IF(L135>0,"Population 1","Population 2"))) -> Excluded | P135: =IF(O135="Excluded","Excluded – nil closing balance",IF(M135>Summary!$C$5,"Above Materiality","Below Materiality")) -> Excluded – nil closing balance | Q135: =IF(P135="Below Materiality",T135,"") | R135: =IF(P135="Above Materiality",COUNTIFS($O$2:$O$1092,O135,$P$2:$P$1092,"Above Materiality",$M$2:$M$1092,">"&M135)+COUNTIFS($O$2:$O$1092,O135,$P$2:$P$1092,"Above Materiality",$M$2:$M$1092,M135,$A$2:$A$1092,"<"&A135)+1,"") | S135: =IF(P135<>"Below Materiality","",IF(Summary!$C$9="Random",COUNTIFS($O$2:$O$1092,O135,$Q$2:$Q$1092,">"&Q135)+1,COUNTIFS($O$2:$O$1092,O135,$P$2:$P$1092,"Below Materiality",$M$2:$M$1092,">"&M135)+COUNTIFS($O$2:$O$1092,O135,$P$2:$P$1092,"Below Materiality",$M$2:$M$1092,M135,$A$2:$A$1092,"<"&A135)+1)) | U135: =IF(R135="","",O135&"|A|"&R135) | V135: =IF(S135="","",O135&"|R|"&S135)
A136: 135 | E136: ACCURATE MANAGEMENT SYSTEM TRADING EST[POLOSYS] | F136: Party-wise closing balance (Opening 0.00; Debit 690.00; Credit 690.00) | G136: AP file | H136: 8 | I136: 0 | J136: 690 | K136: 690 | L136: 0 | M136: =ABS(L136) -> 0 | N136: =IF(L136=0,"Nil balance",IF(G136="AR file",IF(L136>0,"Accounts Receivable","Customer Advances"),IF(L136<0,"Accounts Payable","Supplier Advances"))) -> Nil balance | O136: =IF(L136=0,"Excluded",IF(Summary!$C$4="By ledger",IF(G136="AR file","Population 1","Population 2"),IF(L136>0,"Population 1","Population 2"))) -> Excluded | P136: =IF(O136="Excluded","Excluded – nil closing balance",IF(M136>Summary!$C$5,"Above Materiality","Below Materiality")) -> Excluded – nil closing balance | Q136: =IF(P136="Below Materiality",T136,"") | R136: =IF(P136="Above Materiality",COUNTIFS($O$2:$O$1092,O136,$P$2:$P$1092,"Above Materiality",$M$2:$M$1092,">"&M136)+COUNTIFS($O$2:$O$1092,O136,$P$2:$P$1092,"Above Materiality",$M$2:$M$1092,M136,$A$2:$A$1092,"<"&A136)+1,"") | S136: =IF(P136<>"Below Materiality","",IF(Summary!$C$9="Random",COUNTIFS($O$2:$O$1092,O136,$Q$2:$Q$1092,">"&Q136)+1,COUNTIFS($O$2:$O$1092,O136,$P$2:$P$1092,"Below Materiality",$M$2:$M$1092,">"&M136)+COUNTIFS($O$2:$O$1092,O136,$P$2:$P$1092,"Below Materiality",$M$2:$M$1092,M136,$A$2:$A$1092,"<"&A136)+1)) | U136: =IF(R136="","",O136&"|A|"&R136) | V136: =IF(S136="","",O136&"|R|"&S136)
A137: 136 | E137: ADARK ALBINA TRADING EST | F137: Party-wise closing balance (Opening 0.00; Debit 13,641.30; Credit 13,641.30) | G137: AP file | H137: 9 | I137: 0 | J137: 13641.3 | K137: 13641.3 | L137: 0 | M137: =ABS(L137) -> 0 | N137: =IF(L137=0,"Nil balance",IF(G137="AR file",IF(L137>0,"Accounts Receivable","Customer Advances"),IF(L137<0,"Accounts Payable","Supplier Advances"))) -> Nil balance | O137: =IF(L137=0,"Excluded",IF(Summary!$C$4="By ledger",IF(G137="AR file","Population 1","Population 2"),IF(L137>0,"Population 1","Population 2"))) -> Excluded | P137: =IF(O137="Excluded","Excluded – nil closing balance",IF(M137>Summary!$C$5,"Above Materiality","Below Materiality")) -> Excluded – nil closing balance | Q137: =IF(P137="Below Materiality",T137,"") | R137: =IF(P137="Above Materiality",COUNTIFS($O$2:$O$1092,O137,$P$2:$P$1092,"Above Materiality",$M$2:$M$1092,">"&M137)+COUNTIFS($O$2:$O$1092,O137,$P$2:$P$1092,"Above Materiality",$M$2:$M$1092,M137,$A$2:$A$1092,"<"&A137)+1,"") | S137: =IF(P137<>"Below Materiality","",IF(Summary!$C$9="Random",COUNTIFS($O$2:$O$1092,O137,$Q$2:$Q$1092,">"&Q137)+1,COUNTIFS($O$2:$O$1092,O137,$P$2:$P$1092,"Below Materiality",$M$2:$M$1092,">"&M137)+COUNTIFS($O$2:$O$1092,O137,$P$2:$P$1092,"Below Materiality",$M$2:$M$1092,M137,$A$2:$A$1092,"<"&A137)+1)) | U137: =IF(R137="","",O137&"|A|"&R137) | V137: =IF(S137="","",O137&"|R|"&S137)
A138: 137 | E138: ADDAMEGH FOR INDUSTRIAL SOLUTION EST | F138: Party-wise closing balance (Opening 0.00; Debit 2,470.15; Credit 2,470.15) | G138: AP file | H138: 10 | I138: 0 | J138: 2470.15 | K138: 2470.15 | L138: 0 | M138: =ABS(L138) -> 0 | N138: =IF(L138=0,"Nil balance",IF(G138="AR file",IF(L138>0,"Accounts Receivable","Customer Advances"),IF(L138<0,"Accounts Payable","Supplier Advances"))) -> Nil balance | O138: =IF(L138=0,"Excluded",IF(Summary!$C$4="By ledger",IF(G138="AR file","Population 1","Population 2"),IF(L138>0,"Population 1","Population 2"))) -> Excluded | P138: =IF(O138="Excluded","Excluded – nil closing balance",IF(M138>Summary!$C$5,"Above Materiality","Below Materiality")) -> Excluded – nil closing balance | Q138: =IF(P138="Below Materiality",T138,"") | R138: =IF(P138="Above Materiality",COUNTIFS($O$2:$O$1092,O138,$P$2:$P$1092,"Above Materiality",$M$2:$M$1092,">"&M138)+COUNTIFS($O$2:$O$1092,O138,$P$2:$P$1092,"Above Materiality",$M$2:$M$1092,M138,$A$2:$A$1092,"<"&A138)+1,"") | S138: =IF(P138<>"Below Materiality","",IF(Summary!$C$9="Random",COUNTIFS($O$2:$O$1092,O138,$Q$2:$Q$1092,">"&Q138)+1,COUNTIFS($O$2:$O$1092,O138,$P$2:$P$1092,"Below Materiality",$M$2:$M$1092,">"&M138)+COUNTIFS($O$2:$O$1092,O138,$P$2:$P$1092,"Below Materiality",$M$2:$M$1092,M138,$A$2:$A$1092,"<"&A138)+1)) | U138: =IF(R138="","",O138&"|A|"&R138) | V138: =IF(S138="","",O138&"|R|"&S138)
A139: 138 | E139: AGE STEEL TRADING COMPANY | F139: Party-wise closing balance (Opening 0.00; Debit 5,071.50; Credit 5,071.50) | G139: AP file | H139: 12 | I139: 0 | J139: 5071.5 | K139: 5071.5 | L139: 0 | M139: =ABS(L139) -> 0 | N139: =IF(L139=0,"Nil balance",IF(G139="AR file",IF(L139>0,"Accounts Receivable","Customer Advances"),IF(L139<0,"Accounts Payable","Supplier Advances"))) -> Nil balance | O139: =IF(L139=0,"Excluded",IF(Summary!$C$4="By ledger",IF(G139="AR file","Population 1","Population 2"),IF(L139>0,"Population 1","Population 2"))) -> Excluded | P139: =IF(O139="Excluded","Excluded – nil closing balance",IF(M139>Summary!$C$5,"Above Materiality","Below Materiality")) -> Excluded – nil closing balance | Q139: =IF(P139="Below Materiality",T139,"") | R139: =IF(P139="Above Materiality",COUNTIFS($O$2:$O$1092,O139,$P$2:$P$1092,"Above Materiality",$M$2:$M$1092,">"&M139)+COUNTIFS($O$2:$O$1092,O139,$P$2:$P$1092,"Above Materiality",$M$2:$M$1092,M139,$A$2:$A$1092,"<"&A139)+1,"") | S139: =IF(P139<>"Below Materiality","",IF(Summary!$C$9="Random",COUNTIFS($O$2:$O$1092,O139,$Q$2:$Q$1092,">"&Q139)+1,COUNTIFS($O$2:$O$1092,O139,$P$2:$P$1092,"Below Materiality",$M$2:$M$1092,">"&M139)+COUNTIFS($O$2:$O$1092,O139,$P$2:$P$1092,"Below Materiality",$M$2:$M$1092,M139,$A$2:$A$1092,"<"&A139)+1)) | U139: =IF(R139="","",O139&"|A|"&R139) | V139: =IF(S139="","",O139&"|R|"&S139)
A140: 139 | E140: AHMED AL ZAHRANI EST | F140: Party-wise closing balance (Opening 0.00; Debit 35.00; Credit 35.00) | G140: AP file | H140: 13 | I140: 0 | J140: 35 | K140: 35 | L140: 0 | M140: =ABS(L140) -> 0 | N140: =IF(L140=0,"Nil balance",IF(G140="AR file",IF(L140>0,"Accounts Receivable","Customer Advances"),IF(L140<0,"Accounts Payable","Supplier Advances"))) -> Nil balance | O140: =IF(L140=0,"Excluded",IF(Summary!$C$4="By ledger",IF(G140="AR file","Population 1","Population 2"),IF(L140>0,"Population 1","Population 2"))) -> Excluded | P140: =IF(O140="Excluded","Excluded – nil closing balance",IF(M140>Summary!$C$5,"Above Materiality","Below Materiality")) -> Excluded – nil closing balance | Q140: =IF(P140="Below Materiality",T140,"") | R140: =IF(P140="Above Materiality",COUNTIFS($O$2:$O$1092,O140,$P$2:$P$1092,"Above Materiality",$M$2:$M$1092,">"&M140)+COUNTIFS($O$2:$O$1092,O140,$P$2:$P$1092,"Above Materiality",$M$2:$M$1092,M140,$A$2:$A$1092,"<"&A140)+1,"") | S140: =IF(P140<>"Below Materiality","",IF(Summary!$C$9="Random",COUNTIFS($O$2:$O$1092,O140,$Q$2:$Q$1092,">"&Q140)+1,COUNTIFS($O$2:$O$1092,O140,$P$2:$P$1092,"Below Materiality",$M$2:$M$1092,">"&M140)+COUNTIFS($O$2:$O$1092,O140,$P$2:$P$1092,"Below Materiality",$M$2:$M$1092,M140,$A$2:$A$1092,"<"&A140)+1)) | U140: =IF(R140="","",O140&"|A|"&R140) | V140: =IF(S140="","",O140&"|R|"&S140)
A141: 140 | E141: AHMED M. ALOMAIR SONS CO. | F141: Party-wise closing balance (Opening 0.00; Debit 348,577.11; Credit 348,577.11) | G141: AP file | H141: 14 | I141: 0 | J141: 348577.11 | K141: 348577.11 | L141: 0 | M141: =ABS(L141) -> 0 | N141: =IF(L141=0,"Nil balance",IF(G141="AR file",IF(L141>0,"Accounts Receivable","Customer Advances"),IF(L141<0,"Accounts Payable","Supplier Advances"))) -> Nil balance | O141: =IF(L141=0,"Excluded",IF(Summary!$C$4="By ledger",IF(G141="AR file","Population 1","Population 2"),IF(L141>0,"Population 1","Population 2"))) -> Excluded | P141: =IF(O141="Excluded","Excluded – nil closing balance",IF(M141>Summary!$C$5,"Above Materiality","Below Materiality")) -> Excluded – nil closing balance | Q141: =IF(P141="Below Materiality",T141,"") | R141: =IF(P141="Above Materiality",COUNTIFS($O$2:$O$1092,O141,$P$2:$P$1092,"Above Materiality",$M$2:$M$1092,">"&M141)+COUNTIFS($O$2:$O$1092,O141,$P$2:$P$1092,"Above Materiality",$M$2:$M$1092,M141,$A$2:$A$1092,"<"&A141)+1,"") | S141: =IF(P141<>"Below Materiality","",IF(Summary!$C$9="Random",COUNTIFS($O$2:$O$1092,O141,$Q$2:$Q$1092,">"&Q141)+1,COUNTIFS($O$2:$O$1092,O141,$P$2:$P$1092,"Below Materiality",$M$2:$M$1092,">"&M141)+COUNTIFS($O$2:$O$1092,O141,$P$2:$P$1092,"Below Materiality",$M$2:$M$1092,M141,$A$2:$A$1092,"<"&A141)+1)) | U141: =IF(R141="","",O141&"|A|"&R141) | V141: =IF(S141="","",O141&"|R|"&S141)
... A1092: 1091 | E1092: MOHAMMED ABDUL AZIZ AL-RAZIZ AL-ANQARI SAFETY EQUIPMENT EST | F1092: Party-wise closing balance (Opening 0.00; Debit 60.00; Credit 60.00) | G1092: AR file | H1092: 910 | I1092: 0 | J1092: 60 | K1092: 60 | L1092: 0 | M1092: =ABS(L1092) -> 0 | N1092: =IF(L1092=0,"Nil balance",IF(G1092="AR file",IF(L1092>0,"Accounts Receivable","Customer Advances"),IF(L1092<0,"Accounts Payable","Supplier Advances"))) -> Nil balance | O1092: =IF(L1092=0,"Excluded",IF(Summary!$C$4="By ledger",IF(G1092="AR file","Population 1","Population 2"),IF(L1092>0,"Population 1","Population 2"))) -> Excluded | P1092: =IF(O1092="Excluded","Excluded – nil closing balance",IF(M1092>Summary!$C$5,"Above Materiality","Below Materiality")) -> Excluded – nil closing balance | Q1092: =IF(P1092="Below Materiality",T1092,"") | R1092: =IF(P1092="Above Materiality",COUNTIFS($O$2:$O$1092,O1092,$P$2:$P$1092,"Above Materiality",$M$2:$M$1092,">"&M1092)+COUNTIFS($O$2:$O$1092,O1092,$P$2:$P$1092,"Above Materiality",$M$2:$M$1092,M1092,$A$2:$A$1092,"<"&A1092)+1,"") | S1092: =IF(P1092<>"Below Materiality","",IF(Summary!$C$9="Random",COUNTIFS($O$2:$O$1092,O1092,$Q$2:$Q$1092,">"&Q1092)+1,COUNTIFS($O$2:$O$1092,O1092,$P$2:$P$1092,"Below Materiality",$M$2:$M$1092,">"&M1092)+COUNTIFS($O$2:$O$1092,O1092,$P$2:$P$1092,"Below Materiality",$M$2:$M$1092,M1092,$A$2:$A$1092,"<"&A1092)+1)) | U1092: =IF(R1092="","",O1092&"|A|"&R1092) | V1092: =IF(S1092="","",O1092&"|R|"&S1092)

Sheet Validation
A1: Validation checks
A3: # | B3: Check | C3: Result | D3: Detail
A4: 1 | B4: P1 – population composition (By ledger: AR file only | By side: AR + Supplier Advances) | C4: =IF(Summary!$C$4="By ledger",IF(SUMPRODUCT((Population!$O$2:$O$1092="Population 1")*(Population!$G$2:$G$1092="AP file"))=0,"PASS","FAIL"),IF(AND(COUNTIFS(Population!$N$2:$N$1092,"Accounts Receivable")>0,COUNTIFS(Population!$N$2:$N$1092,"Supplier Advances")>0,SUMPRODUCT((Population!$O$2:$O$1092="Population 1")*((Population!$N$2:$N$1092="Accounts Payable")+(Population!$N$2:$N$1092="Customer Advances")))=0),"PASS","FAIL")) -> PASS | D4: =IF(Summary!$C$4="By ledger","AR file items only: "&COUNTIFS(Population!$O$2:$O$1092,"Population 1"),COUNTIFS(Population!$N$2:$N$1092,"Accounts Receivable")&" AR + "&COUNTIFS(Population!$N$2:$N$1092,"Supplier Advances")&" supplier-advance items") -> AR file items only: 115
A5: 2 | B5: P2 – population composition (By ledger: AP file only | By side: AP + Customer Advances) | C5: =IF(Summary!$C$4="By ledger",IF(SUMPRODUCT((Population!$O$2:$O$1092="Population 2")*(Population!$G$2:$G$1092="AR file"))=0,"PASS","FAIL"),IF(AND(COUNTIFS(Population!$N$2:$N$1092,"Accounts Payable")>0,COUNTIFS(Population!$N$2:$N$1092,"Customer Advances")>0,SUMPRODUCT((Population!$O$2:$O$1092="Population 2")*((Population!$N$2:$N$1092="Accounts Receivable")+(Population!$N$2:$N$1092="Supplier Advances")))=0),"PASS","FAIL")) -> PASS | D5: =IF(Summary!$C$4="By ledger","AP file items only: "&COUNTIFS(Population!$O$2:$O$1092,"Population 2"),COUNTIFS(Population!$N$2:$N$1092,"Accounts Payable")&" AP + "&COUNTIFS(Population!$N$2:$N$1092,"Customer Advances")&" customer-advance items") -> AP file items only: 13
A6: 3 | B6: P1 – every item above materiality is selected | C6: =IF(Summary!C16=Summary!C17,"PASS","FAIL") -> PASS | D6: ="Above: "&Summary!C16&" | selected: "&Summary!C17 -> Above: 37 | selected: 37
A7: 4 | B7: P2 – every item above materiality is selected | C7: =IF(Summary!D16=Summary!D17,"PASS","FAIL") -> PASS | D7: ="Above: "&Summary!D16&" | selected: "&Summary!D17 -> Above: 4 | selected: 4
A8: 5 | B8: P1 – no above-materiality item in the below-materiality selection population | C8: =IF(SUMPRODUCT((Population!$P$2:$P$1092="Above Materiality")*ISNUMBER(Population!$Q$2:$Q$1092))=0,"PASS","FAIL") -> PASS | D8: Selection ranks exist only for below-materiality items
A9: 6 | B9: P2 – no above-materiality item in the below-materiality selection population | C9: =IF(SUMPRODUCT((Population!$P$2:$P$1092="Above Materiality")*ISNUMBER(Population!$Q$2:$Q$1092))=0,"PASS","FAIL") -> PASS | D9: Same test, whole population
A10: 7 | B10: P1 – below-materiality sample size equals calculated n | C10: =IF(Summary!C21=Summary!C7,"PASS","FAIL") -> PASS | D10: ="n = "&Summary!C7&" | selected "&Summary!C21 -> n = 9 | selected 9
A11: 8 | B11: P2 – below-materiality sample size equals calculated n | C11: =IF(Summary!D21=Summary!C8,"PASS","FAIL") -> PASS | D11: ="n = "&Summary!C8&" | selected "&Summary!D21 -> n = 1 | selected 1
A12: 9 | B12: No duplicate within any list, none in both above and random | C12: =IF(SUMPRODUCT(ISNUMBER('1_P1 Above'!$L$5:$L$154)*(COUNTIF('1_P1 Above'!$L$5:$L$154,'1_P1 Above'!$L$5:$L$154)>1))+SUMPRODUCT(ISNUMBER('3_P2 Above'!$L$5:$L$154)*(COUNTIF('3_P2 Above'!$L$5:$L$154,'3_P2 Above'!$L$5:$L$154)>1))+SUMPRODUCT(ISNUMBER('2_P1 Below Sample'!$L$5:$L$104)*(COUNTIF('2_P1 Below Sample'!$L$5:$L$104,'2_P1 Below Sample'!$L$5:$L$104)>1))+SUMPRODUCT(ISNUMBER('4_P2 Below Sample'!$L$5:$L$104)*(COUNTIF('4_P2 Below Sample'!$L$5:$L$104,'4_P2 Below Sample'!$L$5:$L$104)>1))+SUMPRODUCT(ISNUMBER('2_P1 Below Sample'!$L$5:$L$104)*(COUNTIF('1_P1 Above'!$L$5:$L$154,'2_P1 Below Sample'!$L$5:$L$104)>0))+SUMPRODUCT(ISNUMBER('4_P2 Below Sample'!$L$5:$L$104)*(COUNTIF('3_P2 Above'!$L$5:$L$154,'4_P2 Below Sample'!$L$5:$L$104)>0))=0,"PASS","FAIL") -> PASS | D12: Index overlap tested across all four lists
A13: 10 | B13: ABS values correctly calculated | C13: =IF(SUMPRODUCT(--(ABS(Population!$L$2:$L$1092)<>Population!$M$2:$M$1092))=0,"PASS","FAIL") -> PASS | D13: ABS(Original Amount) = Absolute Amount for every row
A14: 11 | B14: Original amounts tie to source control totals (AR 1,063,968.99; AP 30,390.50) | C14: =IF(AND(ABS(SUMIFS(Population!$L$2:$L$1092,Population!$G$2:$G$1092,"AR file")-1063968.99)<0.01,ABS(SUMIFS(Population!$L$2:$L$1092,Population!$G$2:$G$1092,"AP file")-30390.5)<0.01),"PASS","FAIL") -> PASS | D14: =TEXT(SUMIFS(Population!$L$2:$L$1092,Population!$G$2:$G$1092,"AR file"),"#,##0.00")&" | "&TEXT(SUMIFS(Population!$L$2:$L$1092,Population!$G$2:$G$1092,"AP file"),"#,##0.00") -> 1,063,968.99 | 30,390.50
A15: 12 | B15: Materiality = 10,000 as provided | C15: =IF(Summary!C5=10000,"PASS","CHANGED") -> PASS | D15: ="Materiality used: "&TEXT(Summary!C5,"#,##0") -> Materiality used: 10,000
A16: 13 | B16: Above lists sorted by Absolute Amount, largest first | C16: =IF(AND(SUMPRODUCT(ISNUMBER('1_P1 Above'!$G$6:$G$154)*ISNUMBER('1_P1 Above'!$G$5:$G$153)*('1_P1 Above'!$G$6:$G$154>'1_P1 Above'!$G$5:$G$153))=0,SUMPRODUCT(ISNUMBER('3_P2 Above'!$G$6:$G$154)*ISNUMBER('3_P2 Above'!$G$5:$G$153)*('3_P2 Above'!$G$6:$G$154>'3_P2 Above'!$G$5:$G$153))=0),"PASS","FAIL") -> PASS | D16: Both above-materiality lists
A17: 14 | B17: Below-materiality lists sorted correctly (Highest value: Absolute Amount high→low; Random: Random Number high→low) | C17: =IF(AND(IF(Summary!$C$9="Random",SUMPRODUCT(ISNUMBER('2_P1 Below Sample'!$H$6:$H$104)*ISNUMBER('2_P1 Below Sample'!$H$5:$H$103)*('2_P1 Below Sample'!$H$6:$H$104>'2_P1 Below Sample'!$H$5:$H$103))=0,SUMPRODUCT(ISNUMBER('2_P1 Below Sample'!$G$6:$G$104)*ISNUMBER('2_P1 Below Sample'!$G$5:$G$103)*('2_P1 Below Sample'!$G$6:$G$104>'2_P1 Below Sample'!$G$5:$G$103))=0),IF(Summary!$C$9="Random",SUMPRODUCT(ISNUMBER('4_P2 Below Sample'!$H$6:$H$104)*ISNUMBER('4_P2 Below Sample'!$H$5:$H$103)*('4_P2 Below Sample'!$H$6:$H$104>'4_P2 Below Sample'!$H$5:$H$103))=0,SUMPRODUCT(ISNUMBER('4_P2 Below Sample'!$G$6:$G$104)*ISNUMBER('4_P2 Below Sample'!$G$5:$G$103)*('4_P2 Below Sample'!$G$6:$G$104>'4_P2 Below Sample'!$G$5:$G$103))=0)),"PASS","FAIL") -> PASS | D17: Both below-materiality lists
A18: 15 | B18: List capacity (above ≤ 150 per population; n ≤ 100) | C18: =IF(AND(Summary!C16<=150,Summary!D16<=150,N(Summary!C7)<=100,N(Summary!C8)<=100),"PASS","FAIL – extend lists") -> PASS | D18: Sample sheets have fixed capacity
A19: 16 | B19: Missing data: Reference Number / Date / Ledger Code | C19: REVIEW | D19: Blank for all items – source files are party-wise totals
A20: 17 | B20: Nil-balance parties excluded and listed | C20: =IF(COUNTIFS(Population!$N$2:$N$1092,"Nil balance")=COUNTA('Excluded Nil Balance'!$A$5:$A$2000),"PASS","FAIL") -> PASS | D20: =COUNTIFS(Population!$N$2:$N$1092,"Nil balance")&" parties on Excluded sheet" -> 963 parties on Excluded sheet

Sheet 1_P1 Above
A1: ="Excel 1 – "&Summary!$C$12&": Above Materiality" -> Excel 1 – AR Population (AR file: receivables + customer advances): Above Materiality
A2: ="Items listed: "&COUNT(L5:L154)&" | Materiality: "&TEXT(Summary!$C$5,"#,##0") -> Items listed: 37 | Materiality: 10,000
A4: Reference Number | B4: Date | C4: Ledger Code | D4: Ledger Name | E4: Particulars | F4: Original Amount | G4: Absolute Amount | H4: Materiality | I4: Selection Category | J4: Source Ledger | K4: Source (file / row) | L4: Population index (helper)
A5: =IF($L5="","",INDEX(Population!$B$2:$B$1092,$L5)&"") | B5: =IF($L5="","",INDEX(Population!$C$2:$C$1092,$L5)&"") | C5: =IF($L5="","",INDEX(Population!$D$2:$D$1092,$L5)&"") | D5: =IF($L5="","",INDEX(Population!$E$2:$E$1092,$L5)) -> ERAM POWER ELECTRONICS COMPANY | E5: =IF($L5="","",INDEX(Population!$F$2:$F$1092,$L5)) -> Party-wise closing balance (Opening 275,982.75; Debit 955,512.58; Credit 1,129,685.18) | F5: =IF($L5="","",INDEX(Population!$L$2:$L$1092,$L5)) -> 101810.15 | G5: =IF($L5="","",INDEX(Population!$M$2:$M$1092,$L5)) -> 101810.15 | H5: =IF($L5="","",Summary!$C$5) -> 10000 | I5: =IF($L5="","","Above Materiality") -> Above Materiality | J5: =IF($L5="","",INDEX(Population!$N$2:$N$1092,$L5)) -> Accounts Receivable | K5: =IF($L5="","",INDEX(Population!$G$2:$G$1092,$L5)&" / row "&INDEX(Population!$H$2:$H$1092,$L5)) -> AR file / row 409 | L5: =IFERROR(MATCH("Population 1|A|"&ROWS($L$5:L5),Population!$U$2:$U$1092,0),"") -> 2
A6: =IF($L6="","",INDEX(Population!$B$2:$B$1092,$L6)&"") | B6: =IF($L6="","",INDEX(Population!$C$2:$C$1092,$L6)&"") | C6: =IF($L6="","",INDEX(Population!$D$2:$D$1092,$L6)&"") | D6: =IF($L6="","",INDEX(Population!$E$2:$E$1092,$L6)) -> KHALID GENERAL CONTRACTING CO. | E6: =IF($L6="","",INDEX(Population!$F$2:$F$1092,$L6)) -> Party-wise closing balance (Opening 90,920.30; Debit 2,081.50; Credit 2,081.50) | F6: =IF($L6="","",INDEX(Population!$L$2:$L$1092,$L6)) -> 90920.3 | G6: =IF($L6="","",INDEX(Population!$M$2:$M$1092,$L6)) -> 90920.3 | H6: =IF($L6="","",Summary!$C$5) -> 10000 | I6: =IF($L6="","","Above Materiality") -> Above Materiality | J6: =IF($L6="","",INDEX(Population!$N$2:$N$1092,$L6)) -> Accounts Receivable | K6: =IF($L6="","",INDEX(Population!$G$2:$G$1092,$L6)&" / row "&INDEX(Population!$H$2:$H$1092,$L6)) -> AR file / row 276 | L6: =IFERROR(MATCH("Population 1|A|"&ROWS($L$5:L6),Population!$U$2:$U$1092,0),"") -> 3
A7: =IF($L7="","",INDEX(Population!$B$2:$B$1092,$L7)&"") | B7: =IF($L7="","",INDEX(Population!$C$2:$C$1092,$L7)&"") | C7: =IF($L7="","",INDEX(Population!$D$2:$D$1092,$L7)&"") | D7: =IF($L7="","",INDEX(Population!$E$2:$E$1092,$L7)) -> KHALID INDUSTRIAL MARBLE FACTORY | E7: =IF($L7="","",INDEX(Population!$F$2:$F$1092,$L7)) -> Party-wise closing balance (Opening 58,002.75; Debit 0.00; Credit 0.00) | F7: =IF($L7="","",INDEX(Population!$L$2:$L$1092,$L7)) -> 58002.75 | G7: =IF($L7="","",INDEX(Population!$M$2:$M$1092,$L7)) -> 58002.75 | H7: =IF($L7="","",Summary!$C$5) -> 10000 | I7: =IF($L7="","","Above Materiality") -> Above Materiality | J7: =IF($L7="","",INDEX(Population!$N$2:$N$1092,$L7)) -> Accounts Receivable | K7: =IF($L7="","",INDEX(Population!$G$2:$G$1092,$L7)&" / row "&INDEX(Population!$H$2:$H$1092,$L7)) -> AR file / row 16 | L7: =IFERROR(MATCH("Population 1|A|"&ROWS($L$5:L7),Population!$U$2:$U$1092,0),"") -> 5
A8: =IF($L8="","",INDEX(Population!$B$2:$B$1092,$L8)&"") | B8: =IF($L8="","",INDEX(Population!$C$2:$C$1092,$L8)&"") | C8: =IF($L8="","",INDEX(Population!$D$2:$D$1092,$L8)&"") | D8: =IF($L8="","",INDEX(Population!$E$2:$E$1092,$L8)) -> EASTERN SOURCES COMPANY FOR ENERGY AND INDUSTRIAL COMMERCIAL SERVICES | E8: =IF($L8="","",INDEX(Population!$F$2:$F$1092,$L8)) -> Party-wise closing balance (Opening 0.00; Debit 59,641.88; Credit 2,199.38) | F8: =IF($L8="","",INDEX(Population!$L$2:$L$1092,$L8)) -> 57442.5 | G8: =IF($L8="","",INDEX(Population!$M$2:$M$1092,$L8)) -> 57442.5 | H8: =IF($L8="","",Summary!$C$5) -> 10000 | I8: =IF($L8="","","Above Materiality") -> Above Materiality | J8: =IF($L8="","",INDEX(Population!$N$2:$N$1092,$L8)) -> Accounts Receivable | K8: =IF($L8="","",INDEX(Population!$G$2:$G$1092,$L8)&" / row "&INDEX(Population!$H$2:$H$1092,$L8)) -> AR file / row 857 | L8: =IFERROR(MATCH("Population 1|A|"&ROWS($L$5:L8),Population!$U$2:$U$1092,0),"") -> 6
A9: =IF($L9="","",INDEX(Population!$B$2:$B$1092,$L9)&"") | B9: =IF($L9="","",INDEX(Population!$C$2:$C$1092,$L9)&"") | C9: =IF($L9="","",INDEX(Population!$D$2:$D$1092,$L9)&"") | D9: =IF($L9="","",INDEX(Population!$E$2:$E$1092,$L9)) -> JUMEIRAH TRADING COMPANY LIMITED | E9: =IF($L9="","",INDEX(Population!$F$2:$F$1092,$L9)) -> Party-wise closing balance (Opening 0.00; Debit 56,892.80; Credit 772.80) | F9: =IF($L9="","",INDEX(Population!$L$2:$L$1092,$L9)) -> 56120 | G9: =IF($L9="","",INDEX(Population!$M$2:$M$1092,$L9)) -> 56120 | H9: =IF($L9="","",Summary!$C$5) -> 10000 | I9: =IF($L9="","","Above Materiality") -> Above Materiality | J9: =IF($L9="","",INDEX(Population!$N$2:$N$1092,$L9)) -> Accounts Receivable | K9: =IF($L9="","",INDEX(Population!$G$2:$G$1092,$L9)&" / row "&INDEX(Population!$H$2:$H$1092,$L9)) -> AR file / row 478 | L9: =IFERROR(MATCH("Population 1|A|"&ROWS($L$5:L9),Population!$U$2:$U$1092,0),"") -> 7
A10: =IF($L10="","",INDEX(Population!$B$2:$B$1092,$L10)&"") | B10: =IF($L10="","",INDEX(Population!$C$2:$C$1092,$L10)&"") | C10: =IF($L10="","",INDEX(Population!$D$2:$D$1092,$L10)&"") | D10: =IF($L10="","",INDEX(Population!$E$2:$E$1092,$L10)) -> FAB MODERN INDUSTRY CO. | E10: =IF($L10="","",INDEX(Population!$F$2:$F$1092,$L10)) -> Party-wise closing balance (Opening 28,188.06; Debit 27,128.50; Credit 4,150.00) | F10: =IF($L10="","",INDEX(Population!$L$2:$L$1092,$L10)) -> 51166.56 | G10: =IF($L10="","",INDEX(Population!$M$2:$M$1092,$L10)) -> 51166.56 | H10: =IF($L10="","",Summary!$C$5) -> 10000 | I10: =IF($L10="","","Above Materiality") -> Above Materiality | J10: =IF($L10="","",INDEX(Population!$N$2:$N$1092,$L10)) -> Accounts Receivable | K10: =IF($L10="","",INDEX(Population!$G$2:$G$1092,$L10)&" / row "&INDEX(Population!$H$2:$H$1092,$L10)) -> AR file / row 216 | L10: =IFERROR(MATCH("Population 1|A|"&ROWS($L$5:L10),Population!$U$2:$U$1092,0),"") -> 8
A11: =IF($L11="","",INDEX(Population!$B$2:$B$1092,$L11)&"") | B11: =IF($L11="","",INDEX(Population!$C$2:$C$1092,$L11)&"") | C11: =IF($L11="","",INDEX(Population!$D$2:$D$1092,$L11)&"") | D11: =IF($L11="","",INDEX(Population!$E$2:$E$1092,$L11)) -> THE GLOBAL COMPANY FOR MODERN PRINTING & COPYING | E11: =IF($L11="","",INDEX(Population!$F$2:$F$1092,$L11)) -> Party-wise closing balance (Opening 0.00; Debit 22,333.00; Credit 69,036.00) | F11: =IF($L11="","",INDEX(Population!$L$2:$L$1092,$L11)) -> -46703 | G11: =IF($L11="","",INDEX(Population!$M$2:$M$1092,$L11)) -> 46703 | H11: =IF($L11="","",Summary!$C$5) -> 10000 | I11: =IF($L11="","","Above Materiality") -> Above Materiality | J11: =IF($L11="","",INDEX(Population!$N$2:$N$1092,$L11)) -> Customer Advances | K11: =IF($L11="","",INDEX(Population!$G$2:$G$1092,$L11)&" / row "&INDEX(Population!$H$2:$H$1092,$L11)) -> AR file / row 51 | L11: =IFERROR(MATCH("Population 1|A|"&ROWS($L$5:L11),Population!$U$2:$U$1092,0),"") -> 9
A12: =IF($L12="","",INDEX(Population!$B$2:$B$1092,$L12)&"") | B12: =IF($L12="","",INDEX(Population!$C$2:$C$1092,$L12)&"") | C12: =IF($L12="","",INDEX(Population!$D$2:$D$1092,$L12)&"") | D12: =IF($L12="","",INDEX(Population!$E$2:$E$1092,$L12)) -> ERAM FLOORING COMPANY | E12: =IF($L12="","",INDEX(Population!$F$2:$F$1092,$L12)) -> Party-wise closing balance (Opening 0.00; Debit 80,425.25; Credit 39,600.25) | F12: =IF($L12="","",INDEX(Population!$L$2:$L$1092,$L12)) -> 40825 | G12: =IF($L12="","",INDEX(Population!$M$2:$M$1092,$L12)) -> 40825 | H12: =IF($L12="","",Summary!$C$5) -> 10000 | I12: =IF($L12="","","Above Materiality") -> Above Materiality | J12: =IF($L12="","",INDEX(Population!$N$2:$N$1092,$L12)) -> Accounts Receivable | K12: =IF($L12="","",INDEX(Population!$G$2:$G$1092,$L12)&" / row "&INDEX(Population!$H$2:$H$1092,$L12)) -> AR file / row 199 | L12: =IFERROR(MATCH("Population 1|A|"&ROWS($L$5:L12),Population!$U$2:$U$1092,0),"") -> 10
A13: =IF($L13="","",INDEX(Population!$B$2:$B$1092,$L13)&"") | B13: =IF($L13="","",INDEX(Population!$C$2:$C$1092,$L13)&"") | C13: =IF($L13="","",INDEX(Population!$D$2:$D$1092,$L13)&"") | D13: =IF($L13="","",INDEX(Population!$E$2:$E$1092,$L13)) -> FAHAD DILSHAD JAN FACTORY CO. | E13: =IF($L13="","",INDEX(Population!$F$2:$F$1092,$L13)) -> Party-wise closing balance (Opening 95,070.83; Debit 2,541.50; Credit 56,794.00) | F13: =IF($L13="","",INDEX(Population!$L$2:$L$1092,$L13)) -> 40818.33 | G13: =IF($L13="","",INDEX(Population!$M$2:$M$1092,$L13)) -> 40818.33 | H13: =IF($L13="","",Summary!$C$5) -> 10000 | I13: =IF($L13="","","Above Materiality") -> Above Materiality | J13: =IF($L13="","",INDEX(Population!$N$2:$N$1092,$L13)) -> Accounts Receivable | K13: =IF($L13="","",INDEX(Population!$G$2:$G$1092,$L13)&" / row "&INDEX(Population!$H$2:$H$1092,$L13)) -> AR file / row 156 | L13: =IFERROR(MATCH("Population 1|A|"&ROWS($L$5:L13),Population!$U$2:$U$1092,0),"") -> 11
A14: =IF($L14="","",INDEX(Population!$B$2:$B$1092,$L14)&"") | B14: =IF($L14="","",INDEX(Population!$C$2:$C$1092,$L14)&"") | C14: =IF($L14="","",INDEX(Population!$D$2:$D$1092,$L14)&"") | D14: =IF($L14="","",INDEX(Population!$E$2:$E$1092,$L14)) -> AFAN MIDDLE EAST CO. | E14: =IF($L14="","",INDEX(Population!$F$2:$F$1092,$L14)) -> Party-wise closing balance (Opening 0.00; Debit 1,060.00; Credit 41,425.00) | F14: =IF($L14="","",INDEX(Population!$L$2:$L$1092,$L14)) -> -40365 | G14: =IF($L14="","",INDEX(Population!$M$2:$M$1092,$L14)) -> 40365 | H14: =IF($L14="","",Summary!$C$5) -> 10000 | I14: =IF($L14="","","Above Materiality") -> Above Materiality | J14: =IF($L14="","",INDEX(Population!$N$2:$N$1092,$L14)) -> Customer Advances | K14: =IF($L14="","",INDEX(Population!$G$2:$G$1092,$L14)&" / row "&INDEX(Population!$H$2:$H$1092,$L14)) -> AR file / row 301 | L14: =IFERROR(MATCH("Population 1|A|"&ROWS($L$5:L14),Population!$U$2:$U$1092,0),"") -> 12
