Workbook

Sheet Materiality
B2: Materiality | H2: 500
B3: Client | E3: LRC
B4: Audit Area | E4: Risk Assessment | G4: Auditor | H4: 0
B5: Reporting Date | E5: 31 March 2026 | G5: Manager Review | H5: 0
B6: Date Prepared | G6: Partner Review | H6: 0
B7: Comment
B10: 1 | C10: Identify the principal users of the financial statements
C11: Users | F11: Comments
A12: 0 | B12: a
A13: 0 | B13: b
A14: 0 | B14: c
A15: 0 | B15: d
A16: 0 | B16: e
A17: 0 | B17: f
B19: 2 | C19: Describe nature and impact of qualitative considerations
C20: Nature | F20: Impact on audit plan
A21: 0 | B21: a
A22: 0 | B22: b
A23: 0 | B23: c
A24: 0 | B24: d
A25: 0 | B25: e
B27: 3 | C27: Determine quantitative materiality
C28: Planning data | F28: This period anticipated | G28: Previous period | H28: Preceding period
C29: Sales / revenues | F29: 1000000 | H29: 0
C30: Total assets | H30: 0
C31: Total equity | H31: 0
C32: Income before zakat/tax | H32: 0
C33: Previous materiality
B35: 4 | C35: Selecting a Numerical Threshold
E36: Basis | F36: Typical percentages | G36: Percentage applied | H36: Possible materiality
C37: Yes | E37: Sales / revenues | F37: 0.5% - 1% | G37: 0.5 | H37: =IF(C37="Yes",(F29*G37)/100, "") -> 5000
C38: No | E38: Total assets | F38: 0.5% - 1% | G38: 0.5
C39: No | E39: Total equity | F39: 0.01 | G39: 1
C40: No | E40: Income before zakat/tax | F40: 5% - 10% | G40: 5
C42: Based on the above considerations, the materiality is: | G42: SR | H42: =ABS(SUM(H37:H40)*80%) -> 4000

Sheet TB
A1: Ledger Code | B1: Account Name (TB) | C1: TB Debit | D1: TB Credit | E1: Ledger Debit (3 ledgers) | F1: Ledger Credit (3 ledgers) | G1: Debit difference | H1: Credit difference | I1: Reconciliation status | K1: TB debit/credit copied from Formated_TB.xlsx (sheet 'Formated'). Ledger columns are live sums of the three ledgers by Ledger Code.
A2: 10001 | B2: Accumulated Depreciation- Office Interiors | C2: 0 | D2: 3212.0439 | E2: =SUMIF('Revenue Ledger'!$C$2:$C$4500,$A2,'Revenue Ledger'!$G$2:$G$4500)+SUMIF('COGS Ledger'!$C$2:$C$400,$A2,'COGS Ledger'!$G$2:$G$400)+SUMIF('Expense Ledger'!$C$2:$C$800,$A2,'Expense Ledger'!$G$2:$G$800) -> 0 | F2: =SUMIF('Revenue Ledger'!$C$2:$C$4500,$A2,'Revenue Ledger'!$H$2:$H$4500)+SUMIF('COGS Ledger'!$C$2:$C$400,$A2,'COGS Ledger'!$H$2:$H$400)+SUMIF('Expense Ledger'!$C$2:$C$800,$A2,'Expense Ledger'!$H$2:$H$800) -> 0 | G2: =E2-C2 -> 0 | H2: =F2-D2 -> -3212.0439 | I2: =IF(AND(E2=0,F2=0),"No ledger lines",IF(AND(ABS(G2)<1,ABS(H2)<1),"Ties to TB","Difference – review")) -> No ledger lines
A3: 10002 | B3: Accumulated Amortisation- Software- Jbm | C3: 0 | D3: 2041.433 | E3: =SUMIF('Revenue Ledger'!$C$2:$C$4500,$A3,'Revenue Ledger'!$G$2:$G$4500)+SUMIF('COGS Ledger'!$C$2:$C$400,$A3,'COGS Ledger'!$G$2:$G$400)+SUMIF('Expense Ledger'!$C$2:$C$800,$A3,'Expense Ledger'!$G$2:$G$800) -> 0 | F3: =SUMIF('Revenue Ledger'!$C$2:$C$4500,$A3,'Revenue Ledger'!$H$2:$H$4500)+SUMIF('COGS Ledger'!$C$2:$C$400,$A3,'COGS Ledger'!$H$2:$H$400)+SUMIF('Expense Ledger'!$C$2:$C$800,$A3,'Expense Ledger'!$H$2:$H$800) -> 0 | G3: =E3-C3 -> 0 | H3: =F3-D3 -> -2041.433 | I3: =IF(AND(E3=0,F3=0),"No ledger lines",IF(AND(ABS(G3)<1,ABS(H3)<1),"Ties to TB","Difference – review")) -> No ledger lines
A4: 10003 | B4: Accumulated Depreciation- Computer Hardware | C4: 0 | D4: 22579.452 | E4: =SUMIF('Revenue Ledger'!$C$2:$C$4500,$A4,'Revenue Ledger'!$G$2:$G$4500)+SUMIF('COGS Ledger'!$C$2:$C$400,$A4,'COGS Ledger'!$G$2:$G$400)+SUMIF('Expense Ledger'!$C$2:$C$800,$A4,'Expense Ledger'!$G$2:$G$800) -> 0 | F4: =SUMIF('Revenue Ledger'!$C$2:$C$4500,$A4,'Revenue Ledger'!$H$2:$H$4500)+SUMIF('COGS Ledger'!$C$2:$C$400,$A4,'COGS Ledger'!$H$2:$H$400)+SUMIF('Expense Ledger'!$C$2:$C$800,$A4,'Expense Ledger'!$H$2:$H$800) -> 0 | G4: =E4-C4 -> 0 | H4: =F4-D4 -> -22579.452 | I4: =IF(AND(E4=0,F4=0),"No ledger lines",IF(AND(ABS(G4)<1,ABS(H4)<1),"Ties to TB","Difference – review")) -> No ledger lines
A5: 10004 | B5: Cash In Hand | C5: 7000 | D5: 6284.5 | E5: =SUMIF('Revenue Ledger'!$C$2:$C$4500,$A5,'Revenue Ledger'!$G$2:$G$4500)+SUMIF('COGS Ledger'!$C$2:$C$400,$A5,'COGS Ledger'!$G$2:$G$400)+SUMIF('Expense Ledger'!$C$2:$C$800,$A5,'Expense Ledger'!$G$2:$G$800) -> 0 | F5: =SUMIF('Revenue Ledger'!$C$2:$C$4500,$A5,'Revenue Ledger'!$H$2:$H$4500)+SUMIF('COGS Ledger'!$C$2:$C$400,$A5,'COGS Ledger'!$H$2:$H$400)+SUMIF('Expense Ledger'!$C$2:$C$800,$A5,'Expense Ledger'!$H$2:$H$800) -> 0 | G5: =E5-C5 -> -7000 | H5: =F5-D5 -> -6284.5 | I5: =IF(AND(E5=0,F5=0),"No ledger lines",IF(AND(ABS(G5)<1,ABS(H5)<1),"Ties to TB","Difference – review")) -> No ledger lines
A6: 10005 | B6: Computer Hardware | C6: 30606.85 | D6: 0 | E6: =SUMIF('Revenue Ledger'!$C$2:$C$4500,$A6,'Revenue Ledger'!$G$2:$G$4500)+SUMIF('COGS Ledger'!$C$2:$C$400,$A6,'COGS Ledger'!$G$2:$G$400)+SUMIF('Expense Ledger'!$C$2:$C$800,$A6,'Expense Ledger'!$G$2:$G$800) -> 0 | F6: =SUMIF('Revenue Ledger'!$C$2:$C$4500,$A6,'Revenue Ledger'!$H$2:$H$4500)+SUMIF('COGS Ledger'!$C$2:$C$400,$A6,'COGS Ledger'!$H$2:$H$400)+SUMIF('Expense Ledger'!$C$2:$C$800,$A6,'Expense Ledger'!$H$2:$H$800) -> 0 | G6: =E6-C6 -> -30606.85 | H6: =F6-D6 -> 0 | I6: =IF(AND(E6=0,F6=0),"No ledger lines",IF(AND(ABS(G6)<1,ABS(H6)<1),"Ties to TB","Difference – review")) -> No ledger lines
A7: 10006 | B7: Office Interior Cost | C7: 265000 | D7: 0 | E7: =SUMIF('Revenue Ledger'!$C$2:$C$4500,$A7,'Revenue Ledger'!$G$2:$G$4500)+SUMIF('COGS Ledger'!$C$2:$C$400,$A7,'COGS Ledger'!$G$2:$G$400)+SUMIF('Expense Ledger'!$C$2:$C$800,$A7,'Expense Ledger'!$G$2:$G$800) -> 0 | F7: =SUMIF('Revenue Ledger'!$C$2:$C$4500,$A7,'Revenue Ledger'!$H$2:$H$4500)+SUMIF('COGS Ledger'!$C$2:$C$400,$A7,'COGS Ledger'!$H$2:$H$400)+SUMIF('Expense Ledger'!$C$2:$C$800,$A7,'Expense Ledger'!$H$2:$H$800) -> 0 | G7: =E7-C7 -> -265000 | H7: =F7-D7 -> 0 | I7: =IF(AND(E7=0,F7=0),"No ledger lines",IF(AND(ABS(G7)<1,ABS(H7)<1),"Ties to TB","Difference – review")) -> No ledger lines
A8: 10007 | B8: Software- Jbm | C8: 37727.75 | D8: 0 | E8: =SUMIF('Revenue Ledger'!$C$2:$C$4500,$A8,'Revenue Ledger'!$G$2:$G$4500)+SUMIF('COGS Ledger'!$C$2:$C$400,$A8,'COGS Ledger'!$G$2:$G$400)+SUMIF('Expense Ledger'!$C$2:$C$800,$A8,'Expense Ledger'!$G$2:$G$800) -> 0 | F8: =SUMIF('Revenue Ledger'!$C$2:$C$4500,$A8,'Revenue Ledger'!$H$2:$H$4500)+SUMIF('COGS Ledger'!$C$2:$C$400,$A8,'COGS Ledger'!$H$2:$H$400)+SUMIF('Expense Ledger'!$C$2:$C$800,$A8,'Expense Ledger'!$H$2:$H$800) -> 0 | G8: =E8-C8 -> -37727.75 | H8: =F8-D8 -> 0 | I8: =IF(AND(E8=0,F8=0),"No ledger lines",IF(AND(ABS(G8)<1,ABS(H8)<1),"Ties to TB","Difference – review")) -> No ledger lines
A9: 10008 | B9: Health Insurance- Non Saudis | C9: 4252 | D9: 419.37534 | E9: =SUMIF('Revenue Ledger'!$C$2:$C$4500,$A9,'Revenue Ledger'!$G$2:$G$4500)+SUMIF('COGS Ledger'!$C$2:$C$400,$A9,'COGS Ledger'!$G$2:$G$400)+SUMIF('Expense Ledger'!$C$2:$C$800,$A9,'Expense Ledger'!$G$2:$G$800) -> 0 | F9: =SUMIF('Revenue Ledger'!$C$2:$C$4500,$A9,'Revenue Ledger'!$H$2:$H$4500)+SUMIF('COGS Ledger'!$C$2:$C$400,$A9,'COGS Ledger'!$H$2:$H$400)+SUMIF('Expense Ledger'!$C$2:$C$800,$A9,'Expense Ledger'!$H$2:$H$800) -> 0 | G9: =E9-C9 -> -4252 | H9: =F9-D9 -> -419.37534 | I9: =IF(AND(E9=0,F9=0),"No ledger lines",IF(AND(ABS(G9)<1,ABS(H9)<1),"Ties to TB","Difference – review")) -> No ledger lines
A10: 10009 | B10: Health Insurance- Saudi | C10: 7667 | D10: 756.19726 | E10: =SUMIF('Revenue Ledger'!$C$2:$C$4500,$A10,'Revenue Ledger'!$G$2:$G$4500)+SUMIF('COGS Ledger'!$C$2:$C$400,$A10,'COGS Ledger'!$G$2:$G$400)+SUMIF('Expense Ledger'!$C$2:$C$800,$A10,'Expense Ledger'!$G$2:$G$800) -> 0 | F10: =SUMIF('Revenue Ledger'!$C$2:$C$4500,$A10,'Revenue Ledger'!$H$2:$H$4500)+SUMIF('COGS Ledger'!$C$2:$C$400,$A10,'COGS Ledger'!$H$2:$H$400)+SUMIF('Expense Ledger'!$C$2:$C$800,$A10,'Expense Ledger'!$H$2:$H$800) -> 0 | G10: =E10-C10 -> -7667 | H10: =F10-D10 -> -756.19726 | I10: =IF(AND(E10=0,F10=0),"No ledger lines",IF(AND(ABS(G10)<1,ABS(H10)<1),"Ties to TB","Difference – review")) -> No ledger lines
A11: 10010 | B11: Prepaid- Employee Iqama | C11: 35200 | D11: 6474.97 | E11: =SUMIF('Revenue Ledger'!$C$2:$C$4500,$A11,'Revenue Ledger'!$G$2:$G$4500)+SUMIF('COGS Ledger'!$C$2:$C$400,$A11,'COGS Ledger'!$G$2:$G$400)+SUMIF('Expense Ledger'!$C$2:$C$800,$A11,'Expense Ledger'!$G$2:$G$800) -> 0 | F11: =SUMIF('Revenue Ledger'!$C$2:$C$4500,$A11,'Revenue Ledger'!$H$2:$H$4500)+SUMIF('COGS Ledger'!$C$2:$C$400,$A11,'COGS Ledger'!$H$2:$H$400)+SUMIF('Expense Ledger'!$C$2:$C$800,$A11,'Expense Ledger'!$H$2:$H$800) -> 0 | G11: =E11-C11 -> -35200 | H11: =F11-D11 -> -6474.97 | I11: =IF(AND(E11=0,F11=0),"No ledger lines",IF(AND(ABS(G11)<1,ABS(H11)<1),"Ties to TB","Difference – review")) -> No ledger lines
A12: 10011 | B12: Insurance- Deposits | C12: 500000 | D12: 0 | E12: =SUMIF('Revenue Ledger'!$C$2:$C$4500,$A12,'Revenue Ledger'!$G$2:$G$4500)+SUMIF('COGS Ledger'!$C$2:$C$400,$A12,'COGS Ledger'!$G$2:$G$400)+SUMIF('Expense Ledger'!$C$2:$C$800,$A12,'Expense Ledger'!$G$2:$G$800) -> 0 | F12: =SUMIF('Revenue Ledger'!$C$2:$C$4500,$A12,'Revenue Ledger'!$H$2:$H$4500)+SUMIF('COGS Ledger'!$C$2:$C$400,$A12,'COGS Ledger'!$H$2:$H$400)+SUMIF('Expense Ledger'!$C$2:$C$800,$A12,'Expense Ledger'!$H$2:$H$800) -> 0 | G12: =E12-C12 -> -500000 | H12: =F12-D12 -> 0 | I12: =IF(AND(E12=0,F12=0),"No ledger lines",IF(AND(ABS(G12)<1,ABS(H12)<1),"Ties to TB","Difference – review")) -> No ledger lines
A13: 10012 | B13: Rent- Advance | C13: 87600 | D13: 87600 | E13: =SUMIF('Revenue Ledger'!$C$2:$C$4500,$A13,'Revenue Ledger'!$G$2:$G$4500)+SUMIF('COGS Ledger'!$C$2:$C$400,$A13,'COGS Ledger'!$G$2:$G$400)+SUMIF('Expense Ledger'!$C$2:$C$800,$A13,'Expense Ledger'!$G$2:$G$800) -> 0 | F13: =SUMIF('Revenue Ledger'!$C$2:$C$4500,$A13,'Revenue Ledger'!$H$2:$H$4500)+SUMIF('COGS Ledger'!$C$2:$C$400,$A13,'COGS Ledger'!$H$2:$H$400)+SUMIF('Expense Ledger'!$C$2:$C$800,$A13,'Expense Ledger'!$H$2:$H$800) -> 0 | G13: =E13-C13 -> -87600 | H13: =F13-D13 -> -87600 | I13: =IF(AND(E13=0,F13=0),"No ledger lines",IF(AND(ABS(G13)<1,ABS(H13)<1),"Ties to TB","Difference – review")) -> No ledger lines
... A124: 10124 | B124: Gosi Payable | C124: 0 | D124: 4518.08 | E124: =SUMIF('Revenue Ledger'!$C$2:$C$4500,$A124,'Revenue Ledger'!$G$2:$G$4500)+SUMIF('COGS Ledger'!$C$2:$C$400,$A124,'COGS Ledger'!$G$2:$G$400)+SUMIF('Expense Ledger'!$C$2:$C$800,$A124,'Expense Ledger'!$G$2:$G$800) -> 0 | F124: =SUMIF('Revenue Ledger'!$C$2:$C$4500,$A124,'Revenue Ledger'!$H$2:$H$4500)+SUMIF('COGS Ledger'!$C$2:$C$400,$A124,'COGS Ledger'!$H$2:$H$400)+SUMIF('Expense Ledger'!$C$2:$C$800,$A124,'Expense Ledger'!$H$2:$H$800) -> 0 | G124: =E124-C124 -> 0 | H124: =F124-D124 -> -4518.08 | I124: =IF(AND(E124=0,F124=0),"No ledger lines",IF(AND(ABS(G124)<1,ABS(H124)<1),"Ties to TB","Difference – review")) -> No ledger lines

Sheet Ledger Codes
A1: Ledger code map – every ledger account → TB ledger code
A2: Codes come from the TB sheet. Edit a code (yellow) and every ledger, the TB reconciliation and the sample lists update.
A3: Match basis: Exact name match | Mapped – ties to TB (amounts agree to the TB) | Proposed – confirm (best fit, please check) | No TB account – confirm.
A5: # | B5: Account name in ledger (trimmed) | C5: Ledger Code | D5: TB account name | E5: Used in | F5: Match basis | G5: Note | H5: Ledger lines
A6: 1 | B6: AGENCY COMMISSION EXPORT- INC | C6: 10069 | D6: =IF(C6="","",IFERROR(INDEX(TB!$B$2:$B$130,MATCH(C6,TB!$A$2:$A$130,0)),"Code not in TB")) -> Agency Commission Import- Inc | E6: Revenue | F6: Mapped – ties to TB | G6: Export + Import lines together = TB 10069 credit | H6: =IF(B6="","",COUNTIF('Revenue Ledger'!$S$2:$S$4500,B6)+COUNTIF('COGS Ledger'!$S$2:$S$400,B6)+COUNTIF('Expense Ledger'!$S$2:$S$800,B6)) -> 4
A7: 2 | B7: AGENCY COMMISSION IMPORT- INC | C7: 10069 | D7: =IF(C7="","",IFERROR(INDEX(TB!$B$2:$B$130,MATCH(C7,TB!$A$2:$A$130,0)),"Code not in TB")) -> Agency Commission Import- Inc | E7: Revenue | F7: Exact name match | H7: =IF(B7="","",COUNTIF('Revenue Ledger'!$S$2:$S$4500,B7)+COUNTIF('COGS Ledger'!$S$2:$S$400,B7)+COUNTIF('Expense Ledger'!$S$2:$S$800,B7)) -> 7
A8: 3 | B8: AGENCY COMMISSION- T/S HANDLING | C8: 10070 | D8: =IF(C8="","",IFERROR(INDEX(TB!$B$2:$B$130,MATCH(C8,TB!$A$2:$A$130,0)),"Code not in TB")) -> Agency Commission- T/S Handling | E8: Revenue | F8: Exact name match | H8: =IF(B8="","",COUNTIF('Revenue Ledger'!$S$2:$S$4500,B8)+COUNTIF('COGS Ledger'!$S$2:$S$400,B8)+COUNTIF('Expense Ledger'!$S$2:$S$800,B8)) -> 3
A9: 4 | B9: AGENCY COMMISSION- VESSEL HANDLING | C9: 10071 | D9: =IF(C9="","",IFERROR(INDEX(TB!$B$2:$B$130,MATCH(C9,TB!$A$2:$A$130,0)),"Code not in TB")) -> Agency Commission- Vessel Handling | E9: Revenue | F9: Exact name match | H9: =IF(B9="","",COUNTIF('Revenue Ledger'!$S$2:$S$4500,B9)+COUNTIF('COGS Ledger'!$S$2:$S$400,B9)+COUNTIF('Expense Ledger'!$S$2:$S$800,B9)) -> 5
A10: 5 | B10: BERTHING & UNBERTHING CHARGES- INC | C10: 10047 | D10: =IF(C10="","",IFERROR(INDEX(TB!$B$2:$B$130,MATCH(C10,TB!$A$2:$A$130,0)),"Code not in TB")) -> Berthing & Unberthing Charges- Inc | E10: Revenue | F10: Exact name match | H10: =IF(B10="","",COUNTIF('Revenue Ledger'!$S$2:$S$4500,B10)+COUNTIF('COGS Ledger'!$S$2:$S$400,B10)+COUNTIF('Expense Ledger'!$S$2:$S$800,B10)) -> 5
A11: 6 | B11: BILL OF LADING FEE- INC | C11: 10072 | D11: =IF(C11="","",IFERROR(INDEX(TB!$B$2:$B$130,MATCH(C11,TB!$A$2:$A$130,0)),"Code not in TB")) -> Bill Of Lading Fee- Inc | E11: Revenue | F11: Exact name match | H11: =IF(B11="","",COUNTIF('Revenue Ledger'!$S$2:$S$4500,B11)+COUNTIF('COGS Ledger'!$S$2:$S$400,B11)+COUNTIF('Expense Ledger'!$S$2:$S$800,B11)) -> 5
A12: 7 | B12: CONTAINER DAMAGE CHARGES- INC | C12: 10048 | D12: =IF(C12="","",IFERROR(INDEX(TB!$B$2:$B$130,MATCH(C12,TB!$A$2:$A$130,0)),"Code not in TB")) -> Container Damage Charges- Inc | E12: Revenue | F12: Exact name match | H12: =IF(B12="","",COUNTIF('Revenue Ledger'!$S$2:$S$4500,B12)+COUNTIF('COGS Ledger'!$S$2:$S$400,B12)+COUNTIF('Expense Ledger'!$S$2:$S$800,B12)) -> 65
A13: 8 | B13: CONTAINER GATE PASS FEE- INC | C13: 10049 | D13: =IF(C13="","",IFERROR(INDEX(TB!$B$2:$B$130,MATCH(C13,TB!$A$2:$A$130,0)),"Code not in TB")) -> Container Gate Pass Fee- Inc | E13: Revenue | F13: Exact name match | H13: =IF(B13="","",COUNTIF('Revenue Ledger'!$S$2:$S$4500,B13)+COUNTIF('COGS Ledger'!$S$2:$S$400,B13)+COUNTIF('Expense Ledger'!$S$2:$S$800,B13)) -> 558
A14: 9 | B14: DELIVERY ORDER CHARGES- INC | C14: 10073 | D14: =IF(C14="","",IFERROR(INDEX(TB!$B$2:$B$130,MATCH(C14,TB!$A$2:$A$130,0)),"Code not in TB")) -> Delivery Order Charges- Inc | E14: Revenue | F14: Exact name match | H14: =IF(B14="","",COUNTIF('Revenue Ledger'!$S$2:$S$4500,B14)+COUNTIF('COGS Ledger'!$S$2:$S$400,B14)+COUNTIF('Expense Ledger'!$S$2:$S$800,B14)) -> 504
A15: 10 | B15: DEPARTURE FEES & CLEANING CHARGES- INC | C15: 10050 | D15: =IF(C15="","",IFERROR(INDEX(TB!$B$2:$B$130,MATCH(C15,TB!$A$2:$A$130,0)),"Code not in TB")) -> Departure Fees & Cleaning Charges- Inc | E15: Revenue | F15: Exact name match | H15: =IF(B15="","",COUNTIF('Revenue Ledger'!$S$2:$S$4500,B15)+COUNTIF('COGS Ledger'!$S$2:$S$400,B15)+COUNTIF('Expense Ledger'!$S$2:$S$800,B15)) -> 1
A16: 11 | B16: DETENTION COMMISSION- INC | C16: 10067 | D16: =IF(C16="","",IFERROR(INDEX(TB!$B$2:$B$130,MATCH(C16,TB!$A$2:$A$130,0)),"Code not in TB")) -> Detention Commission- Inc | E16: Revenue | F16: Exact name match | H16: =IF(B16="","",COUNTIF('Revenue Ledger'!$S$2:$S$4500,B16)+COUNTIF('COGS Ledger'!$S$2:$S$400,B16)+COUNTIF('Expense Ledger'!$S$2:$S$800,B16)) -> 21
A17: 12 | B17: EDI CHARGES- INC | C17: 10068 | D17: =IF(C17="","",IFERROR(INDEX(TB!$B$2:$B$130,MATCH(C17,TB!$A$2:$A$130,0)),"Code not in TB")) -> Edi Charges- Inc | E17: Revenue | F17: Exact name match | H17: =IF(B17="","",COUNTIF('Revenue Ledger'!$S$2:$S$4500,B17)+COUNTIF('COGS Ledger'!$S$2:$S$400,B17)+COUNTIF('Expense Ledger'!$S$2:$S$800,B17)) -> 504
A18: 13 | B18: FASAH CHARGES- INC | C18: 10066 | D18: =IF(C18="","",IFERROR(INDEX(TB!$B$2:$B$130,MATCH(C18,TB!$A$2:$A$130,0)),"Code not in TB")) -> Fasah Charges- Inc | E18: Revenue | F18: Exact name match | H18: =IF(B18="","",COUNTIF('Revenue Ledger'!$S$2:$S$4500,B18)+COUNTIF('COGS Ledger'!$S$2:$S$400,B18)+COUNTIF('Expense Ledger'!$S$2:$S$800,B18)) -> 562
... A34: 29 | B34: TRANSPORTATION CHARGES | C34: 10065 | D34: =IF(C34="","",IFERROR(INDEX(TB!$B$2:$B$130,MATCH(C34,TB!$A$2:$A$130,0)),"Code not in TB")) -> Transportation Charges | E34: Revenue | F34: Exact name match | H34: =IF(B34="","",COUNTIF('Revenue Ledger'!$S$2:$S$4500,B34)+COUNTIF('COGS Ledger'!$S$2:$S$400,B34)+COUNTIF('Expense Ledger'!$S$2:$S$800,B34)) -> 9
A35: 30 | B35: BERTHING & UNBERTHING CHARGES- EXP | C35: 10047 | D35: =IF(C35="","",IFERROR(INDEX(TB!$B$2:$B$130,MATCH(C35,TB!$A$2:$A$130,0)),"Code not in TB")) -> Berthing & Unberthing Charges- Inc | E35: COGS | F35: Mapped – ties to TB | G35: TB keeps income and cost in one account; debits tie | H35: =IF(B35="","",COUNTIF('Revenue Ledger'!$S$2:$S$4500,B35)+COUNTIF('COGS Ledger'!$S$2:$S$400,B35)+COUNTIF('Expense Ledger'!$S$2:$S$800,B35)) -> 7
A36: 31 | B36: CONTAINER DAMAGE CHARGES- COST | C36: 10048 | D36: =IF(C36="","",IFERROR(INDEX(TB!$B$2:$B$130,MATCH(C36,TB!$A$2:$A$130,0)),"Code not in TB")) -> Container Damage Charges- Inc | E36: COGS | F36: Mapped – ties to TB | G36: Debits tie to TB combined account | H36: =IF(B36="","",COUNTIF('Revenue Ledger'!$S$2:$S$4500,B36)+COUNTIF('COGS Ledger'!$S$2:$S$400,B36)+COUNTIF('Expense Ledger'!$S$2:$S$800,B36)) -> 4
A37: 32 | B37: CONTAINER GATE PASS FEE- EXP | C37: 10049 | D37: =IF(C37="","",IFERROR(INDEX(TB!$B$2:$B$130,MATCH(C37,TB!$A$2:$A$130,0)),"Code not in TB")) -> Container Gate Pass Fee- Inc | E37: COGS | F37: Mapped – ties to TB | G37: Debits tie to TB combined account | H37: =IF(B37="","",COUNTIF('Revenue Ledger'!$S$2:$S$4500,B37)+COUNTIF('COGS Ledger'!$S$2:$S$400,B37)+COUNTIF('Expense Ledger'!$S$2:$S$800,B37)) -> 9
A38: 33 | B38: CONTAINER HOLD CHARGES-EXP | C38: 10084 | D38: =IF(C38="","",IFERROR(INDEX(TB!$B$2:$B$130,MATCH(C38,TB!$A$2:$A$130,0)),"Code not in TB")) -> Container Hold Charges-Exp | E38: COGS | F38: Exact name match | H38: =IF(B38="","",COUNTIF('Revenue Ledger'!$S$2:$S$4500,B38)+COUNTIF('COGS Ledger'!$S$2:$S$400,B38)+COUNTIF('Expense Ledger'!$S$2:$S$800,B38)) -> 1
A39: 34 | B39: DEPARTURE FEES & CLEANING CHARGES- EXP | C39: 10050 | D39: =IF(C39="","",IFERROR(INDEX(TB!$B$2:$B$130,MATCH(C39,TB!$A$2:$A$130,0)),"Code not in TB")) -> Departure Fees & Cleaning Charges- Inc | E39: COGS | F39: Mapped – ties to TB | G39: Debits tie to TB combined account | H39: =IF(B39="","",COUNTIF('Revenue Ledger'!$S$2:$S$4500,B39)+COUNTIF('COGS Ledger'!$S$2:$S$400,B39)+COUNTIF('Expense Ledger'!$S$2:$S$800,B39)) -> 1
A40: 35 | B40: ELECTRONIC AMENDMENT LETTERS | C40: 10068 | D40: =IF(C40="","",IFERROR(INDEX(TB!$B$2:$B$130,MATCH(C40,TB!$A$2:$A$130,0)),"Code not in TB")) -> Edi Charges- Inc | E40: COGS | F40: Mapped – ties to TB | G40: With Electronic Data Interchange, debits = TB 10068 | H40: =IF(B40="","",COUNTIF('Revenue Ledger'!$S$2:$S$4500,B40)+COUNTIF('COGS Ledger'!$S$2:$S$400,B40)+COUNTIF('Expense Ledger'!$S$2:$S$800,B40)) -> 2
A41: 36 | B41: ELECTRONIC DATA INTERCHANGE- EXP | C41: 10068 | D41: =IF(C41="","",IFERROR(INDEX(TB!$B$2:$B$130,MATCH(C41,TB!$A$2:$A$130,0)),"Code not in TB")) -> Edi Charges- Inc | E41: COGS | F41: Mapped – ties to TB | G41: With Electronic Amendment Letters, debits = TB 10068 | H41: =IF(B41="","",COUNTIF('Revenue Ledger'!$S$2:$S$4500,B41)+COUNTIF('COGS Ledger'!$S$2:$S$400,B41)+COUNTIF('Expense Ledger'!$S$2:$S$800,B41)) -> 2
A42: 37 | B42: FASAH APPOINTMENT FEES | C42: 10066 | D42: =IF(C42="","",IFERROR(INDEX(TB!$B$2:$B$130,MATCH(C42,TB!$A$2:$A$130,0)),"Code not in TB")) -> Fasah Charges- Inc | E42: COGS | F42: Mapped – ties to TB | G42: With Fasah Pay Service Charges, debits = TB 10066 | H42: =IF(B42="","",COUNTIF('Revenue Ledger'!$S$2:$S$4500,B42)+COUNTIF('COGS Ledger'!$S$2:$S$400,B42)+COUNTIF('Expense Ledger'!$S$2:$S$800,B42)) -> 8
A43: 38 | B43: FASAH PAY SERVICE CHARGES | C43: 10066 | D43: =IF(C43="","",IFERROR(INDEX(TB!$B$2:$B$130,MATCH(C43,TB!$A$2:$A$130,0)),"Code not in TB")) -> Fasah Charges- Inc | E43: COGS | F43: Mapped – ties to TB | G43: With Fasah Appointment Fees, debits = TB 10066 | H43: =IF(B43="","",COUNTIF('Revenue Ledger'!$S$2:$S$4500,B43)+COUNTIF('COGS Ledger'!$S$2:$S$400,B43)+COUNTIF('Expense Ledger'!$S$2:$S$800,B43)) -> 1
A44: 39 | B44: FRESH WATER SUPPLY | C44: 10079 | D44: =IF(C44="","",IFERROR(INDEX(TB!$B$2:$B$130,MATCH(C44,TB!$A$2:$A$130,0)),"Code not in TB")) -> Fresh Water Supply | E44: COGS | F44: Exact name match | H44: =IF(B44="","",COUNTIF('Revenue Ledger'!$S$2:$S$4500,B44)+COUNTIF('COGS Ledger'!$S$2:$S$400,B44)+COUNTIF('Expense Ledger'!$S$2:$S$800,B44)) -> 4
A45: 40 | B45: FUMIGATION CHARGES | C45: 10080 | D45: =IF(C45="","",IFERROR(INDEX(TB!$B$2:$B$130,MATCH(C45,TB!$A$2:$A$130,0)),"Code not in TB")) -> Fumigation Charges | E45: COGS | F45: Exact name match | H45: =IF(B45="","",COUNTIF('Revenue Ledger'!$S$2:$S$4500,B45)+COUNTIF('COGS Ledger'!$S$2:$S$400,B45)+COUNTIF('Expense Ledger'!$S$2:$S$800,B45)) -> 4
A46: 41 | B46: IMPORT DETENTION-EXP | C46: 10067 | D46: =IF(C46="","",IFERROR(INDEX(TB!$B$2:$B$130,MATCH(C46,TB!$A$2:$A$130,0)),"Code not in TB")) -> Detention Commission- Inc | E46: COGS | F46: Mapped – ties to TB | G46: Debits tie to TB 10067 | H46: =IF(B46="","",COUNTIF('Revenue Ledger'!$S$2:$S$4500,B46)+COUNTIF('COGS Ledger'!$S$2:$S$400,B46)+COUNTIF('Expense Ledger'!$S$2:$S$800,B46)) -> 6
A47: 42 | B47: INVOICE AMENDMENT CHARGES | C47: 10081 | D47: =IF(C47="","",IFERROR(INDEX(TB!$B$2:$B$130,MATCH(C47,TB!$A$2:$A$130,0)),"Code not in TB")) -> Invoice Amendment Charges | E47: COGS | F47: Exact name match | H47: =IF(B47="","",COUNTIF('Revenue Ledger'!$S$2:$S$4500,B47)+COUNTIF('COGS Ledger'!$S$2:$S$400,B47)+COUNTIF('Expense Ledger'!$S$2:$S$800,B47)) -> 1
A48: 43 | B48: LINER EXP UNDER COMPANY ACCOUNT | C48: 10085 | D48: =IF(C48="","",IFERROR(INDEX(TB!$B$2:$B$130,MATCH(C48,TB!$A$2:$A$130,0)),"Code not in TB")) -> Liner Exp Under Company Account | E48: COGS | F48: Exact name match | H48: =IF(B48="","",COUNTIF('Revenue Ledger'!$S$2:$S$4500,B48)+COUNTIF('COGS Ledger'!$S$2:$S$400,B48)+COUNTIF('Expense Ledger'!$S$2:$S$800,B48)) -> 4
A49: 44 | B49: LOLO CHARGES - EXP | C49: 10051 | D49: =IF(C49="","",IFERROR(INDEX(TB!$B$2:$B$130,MATCH(C49,TB!$A$2:$A$130,0)),"Code not in TB")) -> Lolo Charges- Inc | E49: COGS | F49: Mapped – ties to TB | G49: Debits tie to TB combined account | H49: =IF(B49="","",COUNTIF('Revenue Ledger'!$S$2:$S$4500,B49)+COUNTIF('COGS Ledger'!$S$2:$S$400,B49)+COUNTIF('Expense Ledger'!$S$2:$S$800,B49)) -> 11
A50: 45 | B50: OCEAN FREIGHT- EXP | C50: 10052 | D50: =IF(C50="","",IFERROR(INDEX(TB!$B$2:$B$130,MATCH(C50,TB!$A$2:$A$130,0)),"Code not in TB")) -> Ocean Freight- Inc | E50: COGS | F50: Mapped – ties to TB | G50: Debits tie to TB combined account | H50: =IF(B50="","",COUNTIF('Revenue Ledger'!$S$2:$S$4500,B50)+COUNTIF('COGS Ledger'!$S$2:$S$400,B50)+COUNTIF('Expense Ledger'!$S$2:$S$800,B50)) -> 14
A51: 46 | B51: OPERATION RECOVERY COST | C51: 10053 | D51: =IF(C51="","",IFERROR(INDEX(TB!$B$2:$B$130,MATCH(C51,TB!$A$2:$A$130,0)),"Code not in TB")) -> Operation Recovery Cost- Inc | E51: COGS | F51: Mapped – ties to TB | G51: Debits tie to TB combined account | H51: =IF(B51="","",COUNTIF('Revenue Ledger'!$S$2:$S$4500,B51)+COUNTIF('COGS Ledger'!$S$2:$S$400,B51)+COUNTIF('Expense Ledger'!$S$2:$S$800,B51)) -> 49
A52: 47 | B52: PHOTO CHARGE- EXP | C52: 10054 | D52: =IF(C52="","",IFERROR(INDEX(TB!$B$2:$B$130,MATCH(C52,TB!$A$2:$A$130,0)),"Code not in TB")) -> Photo Charges- Inc | E52: COGS | F52: Mapped – ties to TB | G52: With Photo Charges- Exp, debits = TB 10054 | H52: =IF(B52="","",COUNTIF('Revenue Ledger'!$S$2:$S$4500,B52)+COUNTIF('COGS Ledger'!$S$2:$S$400,B52)+COUNTIF('Expense Ledger'!$S$2:$S$800,B52)) -> 8
A53: 48 | B53: PHOTO CHARGES- EXP | C53: 10054 | D53: =IF(C53="","",IFERROR(INDEX(TB!$B$2:$B$130,MATCH(C53,TB!$A$2:$A$130,0)),"Code not in TB")) -> Photo Charges- Inc | E53: COGS | F53: Mapped – ties to TB | G53: With Photo Charge- Exp, debits = TB 10054 | H53: =IF(B53="","",COUNTIF('Revenue Ledger'!$S$2:$S$4500,B53)+COUNTIF('COGS Ledger'!$S$2:$S$400,B53)+COUNTIF('Expense Ledger'!$S$2:$S$800,B53)) -> 1
A54: 49 | B54: PRE ARRIVAL NOTIFICATION | C54: 10086 | D54: =IF(C54="","",IFERROR(INDEX(TB!$B$2:$B$130,MATCH(C54,TB!$A$2:$A$130,0)),"Code not in TB")) -> Pre Arrival Notification | E54: COGS | F54: Exact name match | H54: =IF(B54="","",COUNTIF('Revenue Ledger'!$S$2:$S$4500,B54)+COUNTIF('COGS Ledger'!$S$2:$S$400,B54)+COUNTIF('Expense Ledger'!$S$2:$S$800,B54)) -> 2
A55: 50 | B55: RECOVERY HOLDING CHARGES- EXP | C55: 10055 | D55: =IF(C55="","",IFERROR(INDEX(TB!$B$2:$B$130,MATCH(C55,TB!$A$2:$A$130,0)),"Code not in TB")) -> Recovery Holding Charges- Inc | E55: COGS | F55: Mapped – ties to TB | G55: Debits tie to TB combined account | H55: =IF(B55="","",COUNTIF('Revenue Ledger'!$S$2:$S$4500,B55)+COUNTIF('COGS Ledger'!$S$2:$S$400,B55)+COUNTIF('Expense Ledger'!$S$2:$S$800,B55)) -> 3
A56: 51 | B56: REEFER MONITORING/MAINTENANCE | C56: 10060 | D56: =IF(C56="","",IFERROR(INDEX(TB!$B$2:$B$130,MATCH(C56,TB!$A$2:$A$130,0)),"Code not in TB")) -> Reefer Monitoring/Maintenance | E56: COGS | F56: Exact name match | H56: =IF(B56="","",COUNTIF('Revenue Ledger'!$S$2:$S$4500,B56)+COUNTIF('COGS Ledger'!$S$2:$S$400,B56)+COUNTIF('Expense Ledger'!$S$2:$S$800,B56)) -> 2
...

Sheet Revenue Ledger
A1: Voucher Ref | B1: Date | C1: Ledger Code | D1: Ledger Name | E1: ArAp Ref | F1: Description (Remarks) | G1: Debit | H1: Credit | I1: Original Amount (Dr − Cr) | J1: Absolute Amount | K1: Excluded – account set to Exclude (1 = yes) | L1: Above materiality – selected (1 = yes) | M1: Random No. (fixed) | N1: Possible duplicate | O1: Below-materiality eligible pop. (1 = yes) | P1: Rank key – above | Q1: Rank key – random | R1: Excluded-record key | S1: Account key (trimmed)
A2: DNAMS0025/25 | B2: 45930 | C2: =IF(S2="","",IFERROR(IF(INDEX('Ledger Codes'!$C$6:$C$205,MATCH(S2,'Ledger Codes'!$B$6:$B$205,0))="","",INDEX('Ledger Codes'!$C$6:$C$205,MATCH(S2,'Ledger Codes'!$B$6:$B$205,0))),"")) -> 10069 | D2: AGENCY COMMISSION EXPORT- INC | E2: AGENCY IMPORT COMMISSION- SOA SEP 2025- CAPE CONT UK | F2: AGENCY IMPORT COMMISSION- SOA SEP 2025- CAPE CONT UK | G2: 0 | H2: 20 | I2: =IF(AND(G2="",H2=""),"",N(G2)-N(H2)) -> -20 | J2: =IF(I2="","",ABS(I2)) -> 20 | K2: =IF(S2="","",0) -> 0 | L2: =IF(J2="","",IF(AND(J2>'Revenue Testing'!$E$9,K2=0),1,0)) -> 0 | M2: 0.74713993 | N2: =IF(OR(A2="",I2=""),"",IF(COUNTIFS($A$2:$A$4500,A2,$D$2:$D$4500,D2,$I$2:$I$4500,I2)>1,"Possible duplicate","")) | O2: =IF(J2="","",IF(AND(L2=0,K2=0),1,0)) -> 1 | P2: =IF(L2=1,J2+ROW()/10^7,"") | Q2: =IF(O2=1,M2,"") -> 0.74713993 | R2: =IF(K2=1,ROW(),"") | S2: =IF(D2="","",TRIM(D2)) -> AGENCY COMMISSION EXPORT- INC
A3: DNAMS0026/25 | B3: 45961 | C3: =IF(S3="","",IFERROR(IF(INDEX('Ledger Codes'!$C$6:$C$205,MATCH(S3,'Ledger Codes'!$B$6:$B$205,0))="","",INDEX('Ledger Codes'!$C$6:$C$205,MATCH(S3,'Ledger Codes'!$B$6:$B$205,0))),"")) -> 10069 | D3: AGENCY COMMISSION EXPORT- INC | E3: IMPORT DETENTION COMMISSION FTM OCT 2025- CAPE CONTAINERS UK | F3: IMPORT DETENTION COMMISSION FTM OCT 2025- CAPE CONTAINERS UK AGENCY EXPORT COMMISSION- OCT 2025 AGENCY IMPORT COMMISSION- OCT 2025 | G3: 0 | H3: 20 | I3: =IF(AND(G3="",H3=""),"",N(G3)-N(H3)) -> -20 | J3: =IF(I3="","",ABS(I3)) -> 20 | K3: =IF(S3="","",0) -> 0 | L3: =IF(J3="","",IF(AND(J3>'Revenue Testing'!$E$9,K3=0),1,0)) -> 0 | M3: 0.49935839 | N3: =IF(OR(A3="",I3=""),"",IF(COUNTIFS($A$2:$A$4500,A3,$D$2:$D$4500,D3,$I$2:$I$4500,I3)>1,"Possible duplicate","")) | O3: =IF(J3="","",IF(AND(L3=0,K3=0),1,0)) -> 1 | P3: =IF(L3=1,J3+ROW()/10^7,"") | Q3: =IF(O3=1,M3,"") -> 0.49935839 | R3: =IF(K3=1,ROW(),"") | S3: =IF(D3="","",TRIM(D3)) -> AGENCY COMMISSION EXPORT- INC
A4: DNAMS0027/25 | B4: 45991 | C4: =IF(S4="","",IFERROR(IF(INDEX('Ledger Codes'!$C$6:$C$205,MATCH(S4,'Ledger Codes'!$B$6:$B$205,0))="","",INDEX('Ledger Codes'!$C$6:$C$205,MATCH(S4,'Ledger Codes'!$B$6:$B$205,0))),"")) -> 10069 | D4: AGENCY COMMISSION EXPORT- INC | E4: EXPORT AGENCY COMMISSION- SOA NOV 2025- CAPE CONTAINER UK | F4: EXPORT AGENCY COMMISSION- SOA NOV 2025- CAPE CONTAINER UK AND TRANSPORTATION CHARGES- "TRANSPORTATION CHGS- EMCU5255887 TRIU0777668" JSI-25-4053 | G4: 0 | H4: 80 | I4: =IF(AND(G4="",H4=""),"",N(G4)-N(H4)) -> -80 | J4: =IF(I4="","",ABS(I4)) -> 80 | K4: =IF(S4="","",0) -> 0 | L4: =IF(J4="","",IF(AND(J4>'Revenue Testing'!$E$9,K4=0),1,0)) -> 0 | M4: 0.11101516 | N4: =IF(OR(A4="",I4=""),"",IF(COUNTIFS($A$2:$A$4500,A4,$D$2:$D$4500,D4,$I$2:$I$4500,I4)>1,"Possible duplicate","")) | O4: =IF(J4="","",IF(AND(L4=0,K4=0),1,0)) -> 1 | P4: =IF(L4=1,J4+ROW()/10^7,"") | Q4: =IF(O4=1,M4,"") -> 0.11101516 | R4: =IF(K4=1,ROW(),"") | S4: =IF(D4="","",TRIM(D4)) -> AGENCY COMMISSION EXPORT- INC
A5: DNAMS0028/25 | B5: 46022 | C5: =IF(S5="","",IFERROR(IF(INDEX('Ledger Codes'!$C$6:$C$205,MATCH(S5,'Ledger Codes'!$B$6:$B$205,0))="","",INDEX('Ledger Codes'!$C$6:$C$205,MATCH(S5,'Ledger Codes'!$B$6:$B$205,0))),"")) -> 10069 | D5: AGENCY COMMISSION EXPORT- INC | E5: AGENCY COMMISSION FTM DEC 2025- CAPE CONATINERS UK | F5: AGENCY COMMISSION FTM DEC 2025- CAPE CONATINERS UK | G5: 0 | H5: 20 | I5: =IF(AND(G5="",H5=""),"",N(G5)-N(H5)) -> -20 | J5: =IF(I5="","",ABS(I5)) -> 20 | K5: =IF(S5="","",0) -> 0 | L5: =IF(J5="","",IF(AND(J5>'Revenue Testing'!$E$9,K5=0),1,0)) -> 0 | M5: 0.54971743 | N5: =IF(OR(A5="",I5=""),"",IF(COUNTIFS($A$2:$A$4500,A5,$D$2:$D$4500,D5,$I$2:$I$4500,I5)>1,"Possible duplicate","")) | O5: =IF(J5="","",IF(AND(L5=0,K5=0),1,0)) -> 1 | P5: =IF(L5=1,J5+ROW()/10^7,"") | Q5: =IF(O5=1,M5,"") -> 0.54971743 | R5: =IF(K5=1,ROW(),"") | S5: =IF(D5="","",TRIM(D5)) -> AGENCY COMMISSION EXPORT- INC
A6: DNAMS0024/25 | B6: 45900 | C6: =IF(S6="","",IFERROR(IF(INDEX('Ledger Codes'!$C$6:$C$205,MATCH(S6,'Ledger Codes'!$B$6:$B$205,0))="","",INDEX('Ledger Codes'!$C$6:$C$205,MATCH(S6,'Ledger Codes'!$B$6:$B$205,0))),"")) -> 10069 | D6: AGENCY COMMISSION IMPORT- INC | E6: IMPORT AGENCY COMMISSION- SOA AUG 2025 | F6: IMPORT AGENCY COMMISSION- SOA AUG 2025 | G6: 0 | H6: 300 | I6: =IF(AND(G6="",H6=""),"",N(G6)-N(H6)) -> -300 | J6: =IF(I6="","",ABS(I6)) -> 300 | K6: =IF(S6="","",0) -> 0 | L6: =IF(J6="","",IF(AND(J6>'Revenue Testing'!$E$9,K6=0),1,0)) -> 0 | M6: 0.24180374 | N6: =IF(OR(A6="",I6=""),"",IF(COUNTIFS($A$2:$A$4500,A6,$D$2:$D$4500,D6,$I$2:$I$4500,I6)>1,"Possible duplicate","")) | O6: =IF(J6="","",IF(AND(L6=0,K6=0),1,0)) -> 1 | P6: =IF(L6=1,J6+ROW()/10^7,"") | Q6: =IF(O6=1,M6,"") -> 0.24180374 | R6: =IF(K6=1,ROW(),"") | S6: =IF(D6="","",TRIM(D6)) -> AGENCY COMMISSION IMPORT- INC
A7: DNAMS0012/25 | B7: 45930 | C7: =IF(S7="","",IFERROR(IF(INDEX('Ledger Codes'!$C$6:$C$205,MATCH(S7,'Ledger Codes'!$B$6:$B$205,0))="","",INDEX('Ledger Codes'!$C$6:$C$205,MATCH(S7,'Ledger Codes'!$B$6:$B$205,0))),"")) -> 10069 | D7: AGENCY COMMISSION IMPORT- INC | E7: IMPORT AGENCY COMMISSION- SEP 2025 | F7: IMPORT AGENCY COMMISSION- SEP 2025- CSTAR | G7: 0 | H7: 15525 | I7: =IF(AND(G7="",H7=""),"",N(G7)-N(H7)) -> -15525 | J7: =IF(I7="","",ABS(I7)) -> 15525 | K7: =IF(S7="","",0) -> 0 | L7: =IF(J7="","",IF(AND(J7>'Revenue Testing'!$E$9,K7=0),1,0)) -> 1 | M7: 0.53334083 | N7: =IF(OR(A7="",I7=""),"",IF(COUNTIFS($A$2:$A$4500,A7,$D$2:$D$4500,D7,$I$2:$I$4500,I7)>1,"Possible duplicate","")) | O7: =IF(J7="","",IF(AND(L7=0,K7=0),1,0)) -> 0 | P7: =IF(L7=1,J7+ROW()/10^7,"") -> 15525 | Q7: =IF(O7=1,M7,"") | R7: =IF(K7=1,ROW(),"") | S7: =IF(D7="","",TRIM(D7)) -> AGENCY COMMISSION IMPORT- INC
A8: DNAMS0025/25 | B8: 45930 | C8: =IF(S8="","",IFERROR(IF(INDEX('Ledger Codes'!$C$6:$C$205,MATCH(S8,'Ledger Codes'!$B$6:$B$205,0))="","",INDEX('Ledger Codes'!$C$6:$C$205,MATCH(S8,'Ledger Codes'!$B$6:$B$205,0))),"")) -> 10069 | D8: AGENCY COMMISSION IMPORT- INC | E8: AGENCY IMPORT COMMISSION- SOA SEP 2025- CAPE CONT UK | F8: AGENCY IMPORT COMMISSION- SOA SEP 2025- CAPE CONT UK | G8: 0 | H8: 375 | I8: =IF(AND(G8="",H8=""),"",N(G8)-N(H8)) -> -375 | J8: =IF(I8="","",ABS(I8)) -> 375 | K8: =IF(S8="","",0) -> 0 | L8: =IF(J8="","",IF(AND(J8>'Revenue Testing'!$E$9,K8=0),1,0)) -> 0 | M8: 0.99680177 | N8: =IF(OR(A8="",I8=""),"",IF(COUNTIFS($A$2:$A$4500,A8,$D$2:$D$4500,D8,$I$2:$I$4500,I8)>1,"Possible duplicate","")) | O8: =IF(J8="","",IF(AND(L8=0,K8=0),1,0)) -> 1 | P8: =IF(L8=1,J8+ROW()/10^7,"") | Q8: =IF(O8=1,M8,"") -> 0.99680177 | R8: =IF(K8=1,ROW(),"") | S8: =IF(D8="","",TRIM(D8)) -> AGENCY COMMISSION IMPORT- INC
A9: DNAMS0014/25 | B9: 45961 | C9: =IF(S9="","",IFERROR(IF(INDEX('Ledger Codes'!$C$6:$C$205,MATCH(S9,'Ledger Codes'!$B$6:$B$205,0))="","",INDEX('Ledger Codes'!$C$6:$C$205,MATCH(S9,'Ledger Codes'!$B$6:$B$205,0))),"")) -> 10069 | D9: AGENCY COMMISSION IMPORT- INC | E9: IMPORT AGENCY COMMISSION- OCT 2025 | F9: IMPORT AGENCY COMMISSION- OCT 2025- CSTAR | G9: 0 | H9: 14250 | I9: =IF(AND(G9="",H9=""),"",N(G9)-N(H9)) -> -14250 | J9: =IF(I9="","",ABS(I9)) -> 14250 | K9: =IF(S9="","",0) -> 0 | L9: =IF(J9="","",IF(AND(J9>'Revenue Testing'!$E$9,K9=0),1,0)) -> 1 | M9: 0.53873675 | N9: =IF(OR(A9="",I9=""),"",IF(COUNTIFS($A$2:$A$4500,A9,$D$2:$D$4500,D9,$I$2:$I$4500,I9)>1,"Possible duplicate","")) | O9: =IF(J9="","",IF(AND(L9=0,K9=0),1,0)) -> 0 | P9: =IF(L9=1,J9+ROW()/10^7,"") -> 14250 | Q9: =IF(O9=1,M9,"") | R9: =IF(K9=1,ROW(),"") | S9: =IF(D9="","",TRIM(D9)) -> AGENCY COMMISSION IMPORT- INC
A10: DNAMS0018/25 | B10: 45991 | C10: =IF(S10="","",IFERROR(IF(INDEX('Ledger Codes'!$C$6:$C$205,MATCH(S10,'Ledger Codes'!$B$6:$B$205,0))="","",INDEX('Ledger Codes'!$C$6:$C$205,MATCH(S10,'Ledger Codes'!$B$6:$B$205,0))),"")) -> 10069 | D10: AGENCY COMMISSION IMPORT- INC | E10: IMPORT AGENCY COMMISSION- NOV 2025 | F10: IMPORT AGENCY COMMISSION- NOV 2025- CSTAR | G10: 0 | H10: 3637.5 | I10: =IF(AND(G10="",H10=""),"",N(G10)-N(H10)) -> -3637.5 | J10: =IF(I10="","",ABS(I10)) -> 3637.5 | K10: =IF(S10="","",0) -> 0 | L10: =IF(J10="","",IF(AND(J10>'Revenue Testing'!$E$9,K10=0),1,0)) -> 0 | M10: 0.042012031 | N10: =IF(OR(A10="",I10=""),"",IF(COUNTIFS($A$2:$A$4500,A10,$D$2:$D$4500,D10,$I$2:$I$4500,I10)>1,"Possible duplicate","")) | O10: =IF(J10="","",IF(AND(L10=0,K10=0),1,0)) -> 1 | P10: =IF(L10=1,J10+ROW()/10^7,"") | Q10: =IF(O10=1,M10,"") -> 0.042012031 | R10: =IF(K10=1,ROW(),"") | S10: =IF(D10="","",TRIM(D10)) -> AGENCY COMMISSION IMPORT- INC
A11: DNAMS0004/25 | B11: 46022 | C11: =IF(S11="","",IFERROR(IF(INDEX('Ledger Codes'!$C$6:$C$205,MATCH(S11,'Ledger Codes'!$B$6:$B$205,0))="","",INDEX('Ledger Codes'!$C$6:$C$205,MATCH(S11,'Ledger Codes'!$B$6:$B$205,0))),"")) -> 10069 | D11: AGENCY COMMISSION IMPORT- INC | E11: DR-ALMJDH/00002/202512 | F11: TIME LOG- ASL SHEKOU - ASLS02548E- 1X20' LADEN- AGENCY COMMISSION, SLOT CHARGES, AGENCY RECOVERY CHARGES, DETEMTION CHARGES & COMMISSION | G11: 0 | H11: 75 | I11: =IF(AND(G11="",H11=""),"",N(G11)-N(H11)) -> -75 | J11: =IF(I11="","",ABS(I11)) -> 75 | K11: =IF(S11="","",0) -> 0 | L11: =IF(J11="","",IF(AND(J11>'Revenue Testing'!$E$9,K11=0),1,0)) -> 0 | M11: 0.17742278 | N11: =IF(OR(A11="",I11=""),"",IF(COUNTIFS($A$2:$A$4500,A11,$D$2:$D$4500,D11,$I$2:$I$4500,I11)>1,"Possible duplicate","")) | O11: =IF(J11="","",IF(AND(L11=0,K11=0),1,0)) -> 1 | P11: =IF(L11=1,J11+ROW()/10^7,"") | Q11: =IF(O11=1,M11,"") -> 0.17742278 | R11: =IF(K11=1,ROW(),"") | S11: =IF(D11="","",TRIM(D11)) -> AGENCY COMMISSION IMPORT- INC
A12: DNAMS0028/25 | B12: 46022 | C12: =IF(S12="","",IFERROR(IF(INDEX('Ledger Codes'!$C$6:$C$205,MATCH(S12,'Ledger Codes'!$B$6:$B$205,0))="","",INDEX('Ledger Codes'!$C$6:$C$205,MATCH(S12,'Ledger Codes'!$B$6:$B$205,0))),"")) -> 10069 | D12: AGENCY COMMISSION IMPORT- INC | E12: AGENCY COMMISSION FTM DEC 2025- CAPE CONATINERS UK | F12: AGENCY COMMISSION FTM DEC 2025- CAPE CONATINERS UK | G12: 0 | H12: 150 | I12: =IF(AND(G12="",H12=""),"",N(G12)-N(H12)) -> -150 | J12: =IF(I12="","",ABS(I12)) -> 150 | K12: =IF(S12="","",0) -> 0 | L12: =IF(J12="","",IF(AND(J12>'Revenue Testing'!$E$9,K12=0),1,0)) -> 0 | M12: 0.89911643 | N12: =IF(OR(A12="",I12=""),"",IF(COUNTIFS($A$2:$A$4500,A12,$D$2:$D$4500,D12,$I$2:$I$4500,I12)>1,"Possible duplicate","")) | O12: =IF(J12="","",IF(AND(L12=0,K12=0),1,0)) -> 1 | P12: =IF(L12=1,J12+ROW()/10^7,"") | Q12: =IF(O12=1,M12,"") -> 0.89911643 | R12: =IF(K12=1,ROW(),"") | S12: =IF(D12="","",TRIM(D12)) -> AGENCY COMMISSION IMPORT- INC
A13: DNAMS0013/25 | B13: 45930 | C13: =IF(S13="","",IFERROR(IF(INDEX('Ledger Codes'!$C$6:$C$205,MATCH(S13,'Ledger Codes'!$B$6:$B$205,0))="","",INDEX('Ledger Codes'!$C$6:$C$205,MATCH(S13,'Ledger Codes'!$B$6:$B$205,0))),"")) -> 10070 | D13: AGENCY COMMISSION- T/S HANDLING | E13: T/S AGENCY COMMISSION- SEP 2025 | F13: T/S AGENCY COMMISSION- SEP 2025- CSTAR | G13: 0 | H13: 11756.25 | I13: =IF(AND(G13="",H13=""),"",N(G13)-N(H13)) -> -11756.25 | J13: =IF(I13="","",ABS(I13)) -> 11756.25 | K13: =IF(S13="","",0) -> 0 | L13: =IF(J13="","",IF(AND(J13>'Revenue Testing'!$E$9,K13=0),1,0)) -> 1 | M13: 0.1545322 | N13: =IF(OR(A13="",I13=""),"",IF(COUNTIFS($A$2:$A$4500,A13,$D$2:$D$4500,D13,$I$2:$I$4500,I13)>1,"Possible duplicate","")) | O13: =IF(J13="","",IF(AND(L13=0,K13=0),1,0)) -> 0 | P13: =IF(L13=1,J13+ROW()/10^7,"") -> 11756.25 | Q13: =IF(O13=1,M13,"") | R13: =IF(K13=1,ROW(),"") | S13: =IF(D13="","",TRIM(D13)) -> AGENCY COMMISSION- T/S HANDLING
... A3915: GJAMS0089/25 | B3915: 46022 | C3915: =IF(S3915="","",IFERROR(IF(INDEX('Ledger Codes'!$C$6:$C$205,MATCH(S3915,'Ledger Codes'!$B$6:$B$205,0))="","",INDEX('Ledger Codes'!$C$6:$C$205,MATCH(S3915,'Ledger Codes'!$B$6:$B$205,0))),"")) -> 10059 | D3915: INCOME-SEA FREIGHT EXPORT FCL | E3915: 000007/25 | F3915: Service : SEA FREIGHT EXPORT FCL | G3915: 0 | H3915: 165750 | I3915: =IF(AND(G3915="",H3915=""),"",N(G3915)-N(H3915)) -> -165750 | J3915: =IF(I3915="","",ABS(I3915)) -> 165750 | K3915: =IF(S3915="","",0) -> 0 | L3915: =IF(J3915="","",IF(AND(J3915>'Revenue Testing'!$E$9,K3915=0),1,0)) -> 1 | M3915: 0.13358104 | N3915: =IF(OR(A3915="",I3915=""),"",IF(COUNTIFS($A$2:$A$4500,A3915,$D$2:$D$4500,D3915,$I$2:$I$4500,I3915)>1,"Possible duplicate","")) | O3915: =IF(J3915="","",IF(AND(L3915=0,K3915=0),1,0)) -> 0 | P3915: =IF(L3915=1,J3915+ROW()/10^7,"") -> 165750 | Q3915: =IF(O3915=1,M3915,"") | R3915: =IF(K3915=1,ROW(),"") | S3915: =IF(D3915="","",TRIM(D3915)) -> INCOME-SEA FREIGHT EXPORT FCL
A3916: GJAMS0074/25 | B3916: 45900 | C3916: =IF(S3916="","",IFERROR(IF(INDEX('Ledger Codes'!$C$6:$C$205,MATCH(S3916,'Ledger Codes'!$B$6:$B$205,0))="","",INDEX('Ledger Codes'!$C$6:$C$205,MATCH(S3916,'Ledger Codes'!$B$6:$B$205,0))),"")) -> 10083 | D3916: MISCELLANEOUS INCOME | F3916: PROFIT- SAR 237.5 FROM ALLIED CONTAINER LINE ON FREIGHT FORWARDING DURING AUG 2025 CHARGED OFRT USD 650 WHEREAS SAFEEN FEEDERS CHARGED USD 600 PTI CHARGED SAR 200- FREIGHT WORLD SAR 150 PER CONT USD 50*3.75- SAR 187.5 SAR 200- SAR 150 -SAR 50 TOTAL SAR 237.5 | G3916: 0 | H3916: 237.5 | I3916: =IF(AND(G3916="",H3916=""),"",N(G3916)-N(H3916)) -> -237.5 | J3916: =IF(I3916="","",ABS(I3916)) -> 237.5 | K3916: =IF(S3916="","",0) -> 0 | L3916: =IF(J3916="","",IF(AND(J3916>'Revenue Testing'!$E$9,K3916=0),1,0)) -> 0 | M3916: 0.39909215 | N3916: =IF(OR(A3916="",I3916=""),"",IF(COUNTIFS($A$2:$A$4500,A3916,$D$2:$D$4500,D3916,$I$2:$I$4500,I3916)>1,"Possible duplicate","")) | O3916: =IF(J3916="","",IF(AND(L3916=0,K3916=0),1,0)) -> 1 | P3916: =IF(L3916=1,J3916+ROW()/10^7,"") | Q3916: =IF(O3916=1,M3916,"") -> 0.39909215 | R3916: =IF(K3916=1,ROW(),"") | S3916: =IF(D3916="","",TRIM(D3916)) -> MISCELLANEOUS INCOME
A3917: DNAMS0034/25 | B3917: 45900 | C3917: =IF(S3917="","",IFERROR(IF(INDEX('Ledger Codes'!$C$6:$C$205,MATCH(S3917,'Ledger Codes'!$B$6:$B$205,0))="","",INDEX('Ledger Codes'!$C$6:$C$205,MATCH(S3917,'Ledger Codes'!$B$6:$B$205,0))),"")) -> 10083 | D3917: MISCELLANEOUS INCOME | E3917: BALTIC- OFRT | F3917: OFRT AGREED ON BALTIC- SAR 121500 ACTUAL COST INCURRED AS PER INVOICES RECEIVED- SAR 89391 AGREED EMAIL AND CONFIRMATION OF COST BY MR MOHTISIM AND MR MAHESH AND MR SIDDIQUI IE SAR 92730 REMAINING BALANCE- AL MANARA PROFIT- SAR | G3917: 0 | H3917: 3339 | I3917: =IF(AND(G3917="",H3917=""),"",N(G3917)-N(H3917)) -> -3339 | J3917: =IF(I3917="","",ABS(I3917)) -> 3339 | K3917: =IF(S3917="","",0) -> 0 | L3917: =IF(J3917="","",IF(AND(J3917>'Revenue Testing'!$E$9,K3917=0),1,0)) -> 0 | M3917: 0.42678846 | N3917: =IF(OR(A3917="",I3917=""),"",IF(COUNTIFS($A$2:$A$4500,A3917,$D$2:$D$4500,D3917,$I$2:$I$4500,I3917)>1,"Possible duplicate","")) | O3917: =IF(J3917="","",IF(AND(L3917=0,K3917=0),1,0)) -> 1 | P3917: =IF(L3917=1,J3917+ROW()/10^7,"") | Q3917: =IF(O3917=1,M3917,"") -> 0.42678846 | R3917: =IF(K3917=1,ROW(),"") | S3917: =IF(D3917="","",TRIM(D3917)) -> MISCELLANEOUS INCOME
A3918: GJAMS0092/25 | B3918: 45900 | C3918: =IF(S3918="","",IFERROR(IF(INDEX('Ledger Codes'!$C$6:$C$205,MATCH(S3918,'Ledger Codes'!$B$6:$B$205,0))="","",INDEX('Ledger Codes'!$C$6:$C$205,MATCH(S3918,'Ledger Codes'!$B$6:$B$205,0))),"")) -> 10083 | D3918: MISCELLANEOUS INCOME | E3918: REVERSAL OF GJAMS0074- | F3918: REVERSAL OF GJAMS0074- MISC INCOME ACCOUNTED THROUGH JOB NO AMSSFEF0007- ACL | G3918: 237.5 | H3918: 0 | I3918: =IF(AND(G3918="",H3918=""),"",N(G3918)-N(H3918)) -> 237.5 | J3918: =IF(I3918="","",ABS(I3918)) -> 237.5 | K3918: =IF(S3918="","",0) -> 0 | L3918: =IF(J3918="","",IF(AND(J3918>'Revenue Testing'!$E$9,K3918=0),1,0)) -> 0 | M3918: 0.93515279 | N3918: =IF(OR(A3918="",I3918=""),"",IF(COUNTIFS($A$2:$A$4500,A3918,$D$2:$D$4500,D3918,$I$2:$I$4500,I3918)>1,"Possible duplicate","")) | O3918: =IF(J3918="","",IF(AND(L3918=0,K3918=0),1,0)) -> 1 | P3918: =IF(L3918=1,J3918+ROW()/10^7,"") | Q3918: =IF(O3918=1,M3918,"") -> 0.93515279 | R3918: =IF(K3918=1,ROW(),"") | S3918: =IF(D3918="","",TRIM(D3918)) -> MISCELLANEOUS INCOME
A3919: CNAMS0037/25 | B3919: 45900 | C3919: =IF(S3919="","",IFERROR(IF(INDEX('Ledger Codes'!$C$6:$C$205,MATCH(S3919,'Ledger Codes'!$B$6:$B$205,0))="","",INDEX('Ledger Codes'!$C$6:$C$205,MATCH(S3919,'Ledger Codes'!$B$6:$B$205,0))),"")) -> 10083 | D3919: MISCELLANEOUS INCOME | E3919: REVERSAL OF DNAMS0034- MISC INCOME | F3919: REVERSAL OF DNAMS0034- MISC INCOME- WRONG ENTRY | G3919: 3339 | H3919: 0 | I3919: =IF(AND(G3919="",H3919=""),"",N(G3919)-N(H3919)) -> 3339 | J3919: =IF(I3919="","",ABS(I3919)) -> 3339 | K3919: =IF(S3919="","",0) -> 0 | L3919: =IF(J3919="","",IF(AND(J3919>'Revenue Testing'!$E$9,K3919=0),1,0)) -> 0 | M3919: 0.1413499 | N3919: =IF(OR(A3919="",I3919=""),"",IF(COUNTIFS($A$2:$A$4500,A3919,$D$2:$D$4500,D3919,$I$2:$I$4500,I3919)>1,"Possible duplicate","")) | O3919: =IF(J3919="","",IF(AND(L3919=0,K3919=0),1,0)) -> 1 | P3919: =IF(L3919=1,J3919+ROW()/10^7,"") | Q3919: =IF(O3919=1,M3919,"") -> 0.1413499 | R3919: =IF(K3919=1,ROW(),"") | S3919: =IF(D3919="","",TRIM(D3919)) -> MISCELLANEOUS INCOME
A3920: DNAMS0009/25 | B3920: 45905 | C3920: =IF(S3920="","",IFERROR(IF(INDEX('Ledger Codes'!$C$6:$C$205,MATCH(S3920,'Ledger Codes'!$B$6:$B$205,0))="","",INDEX('Ledger Codes'!$C$6:$C$205,MATCH(S3920,'Ledger Codes'!$B$6:$B$205,0))),"")) -> 10083 | D3920: MISCELLANEOUS INCOME | E3920: 11184 | F3920: INV 11184 FW SUPPLY 180 MT @ USD 11/SAR 41.25 PER MT- USD 3 PER MT PROFIT | G3920: 0 | H3920: 1350.03 | I3920: =IF(AND(G3920="",H3920=""),"",N(G3920)-N(H3920)) -> -1350.03 | J3920: =IF(I3920="","",ABS(I3920)) -> 1350.03 | K3920: =IF(S3920="","",0) -> 0 | L3920: =IF(J3920="","",IF(AND(J3920>'Revenue Testing'!$E$9,K3920=0),1,0)) -> 0 | M3920: 0.31243604 | N3920: =IF(OR(A3920="",I3920=""),"",IF(COUNTIFS($A$2:$A$4500,A3920,$D$2:$D$4500,D3920,$I$2:$I$4500,I3920)>1,"Possible duplicate","")) | O3920: =IF(J3920="","",IF(AND(L3920=0,K3920=0),1,0)) -> 1 | P3920: =IF(L3920=1,J3920+ROW()/10^7,"") | Q3920: =IF(O3920=1,M3920,"") -> 0.31243604 | R3920: =IF(K3920=1,ROW(),"") | S3920: =IF(D3920="","",TRIM(D3920)) -> MISCELLANEOUS INCOME
A3921: GJAMS0022/25 | B3921: 45907 | C3921: =IF(S3921="","",IFERROR(IF(INDEX('Ledger Codes'!$C$6:$C$205,MATCH(S3921,'Ledger Codes'!$B$6:$B$205,0))="","",INDEX('Ledger Codes'!$C$6:$C$205,MATCH(S3921,'Ledger Codes'!$B$6:$B$205,0))),"")) -> 10083 | D3921: MISCELLANEOUS INCOME | F3921: EXCESS AMOUNT PAID FOR DO INV- SAR 207.5- PROFIT SINCE 8 MONTHS CUSTOMER NOT FOLLOWED UP FOR CLAIM CHARGED AS PER 40HC INSTEAD OF 20DV | G3921: 0 | H3921: 207.5 | I3921: =IF(AND(G3921="",H3921=""),"",N(G3921)-N(H3921)) -> -207.5 | J3921: =IF(I3921="","",ABS(I3921)) -> 207.5 | K3921: =IF(S3921="","",0) -> 0 | L3921: =IF(J3921="","",IF(AND(J3921>'Revenue Testing'!$E$9,K3921=0),1,0)) -> 0 | M3921: 0.13358422 | N3921: =IF(OR(A3921="",I3921=""),"",IF(COUNTIFS($A$2:$A$4500,A3921,$D$2:$D$4500,D3921,$I$2:$I$4500,I3921)>1,"Possible duplicate","")) | O3921: =IF(J3921="","",IF(AND(L3921=0,K3921=0),1,0)) -> 1 | P3921: =IF(L3921=1,J3921+ROW()/10^7,"") | Q3921: =IF(O3921=1,M3921,"") -> 0.13358422 | R3921: =IF(K3921=1,ROW(),"") | S3921: =IF(D3921="","",TRIM(D3921)) -> MISCELLANEOUS INCOME
A3922: GJAMS0024/25 | B3922: 45907 | C3922: =IF(S3922="","",IFERROR(IF(INDEX('Ledger Codes'!$C$6:$C$205,MATCH(S3922,'Ledger Codes'!$B$6:$B$205,0))="","",INDEX('Ledger Codes'!$C$6:$C$205,MATCH(S3922,'Ledger Codes'!$B$6:$B$205,0))),"")) -> 10083 | D3922: MISCELLANEOUS INCOME | F3922: EXCESS AMT PAID SAR 9- CSDSHA032816 GOLDEN AUTOMATED BATTERY- CSTAR | G3922: 0 | H3922: 9 | I3922: =IF(AND(G3922="",H3922=""),"",N(G3922)-N(H3922)) -> -9 | J3922: =IF(I3922="","",ABS(I3922)) -> 9 | K3922: =IF(S3922="","",0) -> 0 | L3922: =IF(J3922="","",IF(AND(J3922>'Revenue Testing'!$E$9,K3922=0),1,0)) -> 0 | M3922: 0.38983589 | N3922: =IF(OR(A3922="",I3922=""),"",IF(COUNTIFS($A$2:$A$4500,A3922,$D$2:$D$4500,D3922,$I$2:$I$4500,I3922)>1,"Possible duplicate","")) | O3922: =IF(J3922="","",IF(AND(L3922=0,K3922=0),1,0)) -> 1 | P3922: =IF(L3922=1,J3922+ROW()/10^7,"") | Q3922: =IF(O3922=1,M3922,"") -> 0.38983589 | R3922: =IF(K3922=1,ROW(),"") | S3922: =IF(D3922="","",TRIM(D3922)) -> MISCELLANEOUS INCOME
A3923: GJAMS0026/25 | B3923: 45907 | C3923: =IF(S3923="","",IFERROR(IF(INDEX('Ledger Codes'!$C$6:$C$205,MATCH(S3923,'Ledger Codes'!$B$6:$B$205,0))="","",INDEX('Ledger Codes'!$C$6:$C$205,MATCH(S3923,'Ledger Codes'!$B$6:$B$205,0))),"")) -> 10083 | D3923: MISCELLANEOUS INCOME | F3923: EXCESS AMT PAID SAR 207.5- CSDSHA032863 CHARGED AS PER 40HC INSTEAD OF 20DV | G3923: 0 | H3923: 207.5 | I3923: =IF(AND(G3923="",H3923=""),"",N(G3923)-N(H3923)) -> -207.5 | J3923: =IF(I3923="","",ABS(I3923)) -> 207.5 | K3923: =IF(S3923="","",0) -> 0 | L3923: =IF(J3923="","",IF(AND(J3923>'Revenue Testing'!$E$9,K3923=0),1,0)) -> 0 | M3923: 0.40360017 | N3923: =IF(OR(A3923="",I3923=""),"",IF(COUNTIFS($A$2:$A$4500,A3923,$D$2:$D$4500,D3923,$I$2:$I$4500,I3923)>1,"Possible duplicate","")) | O3923: =IF(J3923="","",IF(AND(L3923=0,K3923=0),1,0)) -> 1 | P3923: =IF(L3923=1,J3923+ROW()/10^7,"") | Q3923: =IF(O3923=1,M3923,"") -> 0.40360017 | R3923: =IF(K3923=1,ROW(),"") | S3923: =IF(D3923="","",TRIM(D3923)) -> MISCELLANEOUS INCOME
A3924: GJAMS0027/25 | B3924: 45908 | C3924: =IF(S3924="","",IFERROR(IF(INDEX('Ledger Codes'!$C$6:$C$205,MATCH(S3924,'Ledger Codes'!$B$6:$B$205,0))="","",INDEX('Ledger Codes'!$C$6:$C$205,MATCH(S3924,'Ledger Codes'!$B$6:$B$205,0))),"")) -> 10083 | D3924: MISCELLANEOUS INCOME | F3924: EXCESS AMT SAR 134 PAID FOR REEFER SURCHARGE FOR 3 DAYS INSTEAD OF 2 DAYS | G3924: 0 | H3924: 134 | I3924: =IF(AND(G3924="",H3924=""),"",N(G3924)-N(H3924)) -> -134 | J3924: =IF(I3924="","",ABS(I3924)) -> 134 | K3924: =IF(S3924="","",0) -> 0 | L3924: =IF(J3924="","",IF(AND(J3924>'Revenue Testing'!$E$9,K3924=0),1,0)) -> 0 | M3924: 0.81339547 | N3924: =IF(OR(A3924="",I3924=""),"",IF(COUNTIFS($A$2:$A$4500,A3924,$D$2:$D$4500,D3924,$I$2:$I$4500,I3924)>1,"Possible duplicate","")) | O3924: =IF(J3924="","",IF(AND(L3924=0,K3924=0),1,0)) -> 1 | P3924: =IF(L3924=1,J3924+ROW()/10^7,"") | Q3924: =IF(O3924=1,M3924,"") -> 0.81339547 | R3924: =IF(K3924=1,ROW(),"") | S3924: =IF(D3924="","",TRIM(D3924)) -> MISCELLANEOUS INCOME
A3925: GJAMS0023/25 | B3925: 45929 | C3925: =IF(S3925="","",IFERROR(IF(INDEX('Ledger Codes'!$C$6:$C$205,MATCH(S3925,'Ledger Codes'!$B$6:$B$205,0))="","",INDEX('Ledger Codes'!$C$6:$C$205,MATCH(S3925,'Ledger Codes'!$B$6:$B$205,0))),"")) -> 10083 | D3925: MISCELLANEOUS INCOME | F3925: PAYMENT EXCESS SAR 35 RECEIVED ON EXPORT SHIPMENT INV TO GLOBIWN FORWARDING CO- CAPELINE LLC | G3925: 0 | H3925: 35 | I3925: =IF(AND(G3925="",H3925=""),"",N(G3925)-N(H3925)) -> -35 | J3925: =IF(I3925="","",ABS(I3925)) -> 35 | K3925: =IF(S3925="","",0) -> 0 | L3925: =IF(J3925="","",IF(AND(J3925>'Revenue Testing'!$E$9,K3925=0),1,0)) -> 0 | M3925: 0.47724031 | N3925: =IF(OR(A3925="",I3925=""),"",IF(COUNTIFS($A$2:$A$4500,A3925,$D$2:$D$4500,D3925,$I$2:$I$4500,I3925)>1,"Possible duplicate","")) | O3925: =IF(J3925="","",IF(AND(L3925=0,K3925=0),1,0)) -> 1 | P3925: =IF(L3925=1,J3925+ROW()/10^7,"") | Q3925: =IF(O3925=1,M3925,"") -> 0.47724031 | R3925: =IF(K3925=1,ROW(),"") | S3925: =IF(D3925="","",TRIM(D3925)) -> MISCELLANEOUS INCOME
A3926: GJAMS0028/25 | B3926: 45942 | C3926: =IF(S3926="","",IFERROR(IF(INDEX('Ledger Codes'!$C$6:$C$205,MATCH(S3926,'Ledger Codes'!$B$6:$B$205,0))="","",INDEX('Ledger Codes'!$C$6:$C$205,MATCH(S3926,'Ledger Codes'!$B$6:$B$205,0))),"")) -> 10083 | D3926: MISCELLANEOUS INCOME | F3926: EXCESS DETENTION PAID SAR 120- SAUDI INDUSTRIES FOR PVC WINDOWS CO. LTD. | G3926: 0 | H3926: 120 | I3926: =IF(AND(G3926="",H3926=""),"",N(G3926)-N(H3926)) -> -120 | J3926: =IF(I3926="","",ABS(I3926)) -> 120 | K3926: =IF(S3926="","",0) -> 0 | L3926: =IF(J3926="","",IF(AND(J3926>'Revenue Testing'!$E$9,K3926=0),1,0)) -> 0 | M3926: 0.58032359 | N3926: =IF(OR(A3926="",I3926=""),"",IF(COUNTIFS($A$2:$A$4500,A3926,$D$2:$D$4500,D3926,$I$2:$I$4500,I3926)>1,"Possible duplicate","")) | O3926: =IF(J3926="","",IF(AND(L3926=0,K3926=0),1,0)) -> 1 | P3926: =IF(L3926=1,J3926+ROW()/10^7,"") | Q3926: =IF(O3926=1,M3926,"") -> 0.58032359 | R3926: =IF(K3926=1,ROW(),"") | S3926: =IF(D3926="","",TRIM(D3926)) -> MISCELLANEOUS INCOME
A3927: DNAMS0022/25 | B3927: 45961 | C3927: =IF(S3927="","",IFERROR(IF(INDEX('Ledger Codes'!$C$6:$C$205,MATCH(S3927,'Ledger Codes'!$B$6:$B$205,0))="","",INDEX('Ledger Codes'!$C$6:$C$205,MATCH(S3927,'Ledger Codes'!$B$6:$B$205,0))),"")) -> 10083 | D3927: MISCELLANEOUS INCOME | E3927: 2369993- OVER THC CHARGED TO CSTAR | F3927: CSTAR-- 2369993- OVER THC CHARGED TO CSTAR FOR VESSEL CMA CGM ROSSINI - CCRO0RDMBE1MA ON T/S BASIS ON 40' | G3927: 0 | H3927: 210 | I3927: =IF(AND(G3927="",H3927=""),"",N(G3927)-N(H3927)) -> -210 | J3927: =IF(I3927="","",ABS(I3927)) -> 210 | K3927: =IF(S3927="","",0) -> 0 | L3927: =IF(J3927="","",IF(AND(J3927>'Revenue Testing'!$E$9,K3927=0),1,0)) -> 0 | M3927: 0.31755365 | N3927: =IF(OR(A3927="",I3927=""),"",IF(COUNTIFS($A$2:$A$4500,A3927,$D$2:$D$4500,D3927,$I$2:$I$4500,I3927)>1,"Possible duplicate","")) | O3927: =IF(J3927="","",IF(AND(L3927=0,K3927=0),1,0)) -> 1 | P3927: =IF(L3927=1,J3927+ROW()/10^7,"") | Q3927: =IF(O3927=1,M3927,"") -> 0.31755365 | R3927: =IF(K3927=1,ROW(),"") | S3927: =IF(D3927="","",TRIM(D3927)) -> MISCELLANEOUS INCOME
A3928: GJAMS0031/25 | B3928: 45965 | C3928: =IF(S3928="","",IFERROR(IF(INDEX('Ledger Codes'!$C$6:$C$205,MATCH(S3928,'Ledger Codes'!$B$6:$B$205,0))="","",INDEX('Ledger Codes'!$C$6:$C$205,MATCH(S3928,'Ledger Codes'!$B$6:$B$205,0))),"")) -> 10083 | D3928: MISCELLANEOUS INCOME | F3928: RSGT- 2373434- RSGT- CLF- CUL BANGKOK - BANK2538E- LOAD T/S EMPTY- 2X20'- SAR 149.5 34X40'- SAR 224.5 SAR 224.5 EXTRA CHARGED TO CSTAR ACTUAL INV AMT- SAR 7707.5 CHARGED SAR 7932- REF INV TO CSTAR | G3928: 0 | H3928: 224.5 | I3928: =IF(AND(G3928="",H3928=""),"",N(G3928)-N(H3928)) -> -224.5 | J3928: =IF(I3928="","",ABS(I3928)) -> 224.5 | K3928: =IF(S3928="","",0) -> 0 | L3928: =IF(J3928="","",IF(AND(J3928>'Revenue Testing'!$E$9,K3928=0),1,0)) -> 0 | M3928: 0.64838014 | N3928: =IF(OR(A3928="",I3928=""),"",IF(COUNTIFS($A$2:$A$4500,A3928,$D$2:$D$4500,D3928,$I$2:$I$4500,I3928)>1,"Possible duplicate","")) | O3928: =IF(J3928="","",IF(AND(L3928=0,K3928=0),1,0)) -> 1 | P3928: =IF(L3928=1,J3928+ROW()/10^7,"") | Q3928: =IF(O3928=1,M3928,"") -> 0.64838014 | R3928: =IF(K3928=1,ROW(),"") | S3928: =IF(D3928="","",TRIM(D3928)) -> MISCELLANEOUS INCOME
A3929: GJAMS0025/25 | B3929: 45971 | C3929: =IF(S3929="","",IFERROR(IF(INDEX('Ledger Codes'!$C$6:$C$205,MATCH(S3929,'Ledger Codes'!$B$6:$B$205,0))="","",INDEX('Ledger Codes'!$C$6:$C$205,MATCH(S3929,'Ledger Codes'!$B$6:$B$205,0))),"")) -> 10083 | D3929: MISCELLANEOUS INCOME | F3929: EXCESS DETENTION PAID AMT SAR 120- CSDIST002912- CSTAR | G3929: 0 | H3929: 120 | I3929: =IF(AND(G3929="",H3929=""),"",N(G3929)-N(H3929)) -> -120 | J3929: =IF(I3929="","",ABS(I3929)) -> 120 | K3929: =IF(S3929="","",0) -> 0 | L3929: =IF(J3929="","",IF(AND(J3929>'Revenue Testing'!$E$9,K3929=0),1,0)) -> 0 | M3929: 0.9966784 | N3929: =IF(OR(A3929="",I3929=""),"",IF(COUNTIFS($A$2:$A$4500,A3929,$D$2:$D$4500,D3929,$I$2:$I$4500,I3929)>1,"Possible duplicate","")) | O3929: =IF(J3929="","",IF(AND(L3929=0,K3929=0),1,0)) -> 1 | P3929: =IF(L3929=1,J3929+ROW()/10^7,"") | Q3929: =IF(O3929=1,M3929,"") -> 0.9966784 | R3929: =IF(K3929=1,ROW(),"") | S3929: =IF(D3929="","",TRIM(D3929)) -> MISCELLANEOUS INCOME
A3930: GJAMS0019/25 | B3930: 45972 | C3930: =IF(S3930="","",IFERROR(IF(INDEX('Ledger Codes'!$C$6:$C$205,MATCH(S3930,'Ledger Codes'!$B$6:$B$205,0))="","",INDEX('Ledger Codes'!$C$6:$C$205,MATCH(S3930,'Ledger Codes'!$B$6:$B$205,0))),"")) -> 10083 | D3930: MISCELLANEOUS INCOME | F3930: EXCESS DETENTION SAR 60- BL CSDSHA034080 | G3930: 0 | H3930: 60 | I3930: =IF(AND(G3930="",H3930=""),"",N(G3930)-N(H3930)) -> -60 | J3930: =IF(I3930="","",ABS(I3930)) -> 60 | K3930: =IF(S3930="","",0) -> 0 | L3930: =IF(J3930="","",IF(AND(J3930>'Revenue Testing'!$E$9,K3930=0),1,0)) -> 0 | M3930: 0.66049409 | N3930: =IF(OR(A3930="",I3930=""),"",IF(COUNTIFS($A$2:$A$4500,A3930,$D$2:$D$4500,D3930,$I$2:$I$4500,I3930)>1,"Possible duplicate","")) | O3930: =IF(J3930="","",IF(AND(L3930=0,K3930=0),1,0)) -> 1 | P3930: =IF(L3930=1,J3930+ROW()/10^7,"") | Q3930: =IF(O3930=1,M3930,"") -> 0.66049409 | R3930: =IF(K3930=1,ROW(),"") | S3930: =IF(D3930="","",TRIM(D3930)) -> MISCELLANEOUS INCOME
A3931: DNAMS0010/25 | B3931: 45979 | C3931: =IF(S3931="","",IFERROR(IF(INDEX('Ledger Codes'!$C$6:$C$205,MATCH(S3931,'Ledger Codes'!$B$6:$B$205,0))="","",INDEX('Ledger Codes'!$C$6:$C$205,MATCH(S3931,'Ledger Codes'!$B$6:$B$205,0))),"")) -> 10083 | D3931: MISCELLANEOUS INCOME | E3931: 11345 | F3931: INV 11345 CSTAR FW SUPPLY 120 MT USD 3 PER MT PROFIT | G3931: 0 | H3931: 900.08 | I3931: =IF(AND(G3931="",H3931=""),"",N(G3931)-N(H3931)) -> -900.08 | J3931: =IF(I3931="","",ABS(I3931)) -> 900.08 | K3931: =IF(S3931="","",0) -> 0 | L3931: =IF(J3931="","",IF(AND(J3931>'Revenue Testing'!$E$9,K3931=0),1,0)) -> 0 | M3931: 0.11284376 | N3931: =IF(OR(A3931="",I3931=""),"",IF(COUNTIFS($A$2:$A$4500,A3931,$D$2:$D$4500,D3931,$I$2:$I$4500,I3931)>1,"Possible duplicate","")) | O3931: =IF(J3931="","",IF(AND(L3931=0,K3931=0),1,0)) -> 1 | P3931: =IF(L3931=1,J3931+ROW()/10^7,"") | Q3931: =IF(O3931=1,M3931,"") -> 0.11284376 | R3931: =IF(K3931=1,ROW(),"") | S3931: =IF(D3931="","",TRIM(D3931)) -> MISCELLANEOUS INCOME
A3932: GJAMS0020/25 | B3932: 45984 | C3932: =IF(S3932="","",IFERROR(IF(INDEX('Ledger Codes'!$C$6:$C$205,MATCH(S3932,'Ledger Codes'!$B$6:$B$205,0))="","",INDEX('Ledger Codes'!$C$6:$C$205,MATCH(S3932,'Ledger Codes'!$B$6:$B$205,0))),"")) -> 10083 | D3932: MISCELLANEOUS INCOME | F3932: EXCESS DETENTION PAID SAR 440- BL CSDSHA033634 AL-MUSAMIR MEMIZA AL-FAKHRA FOR TRADING | G3932: 0 | H3932: 440 | I3932: =IF(AND(G3932="",H3932=""),"",N(G3932)-N(H3932)) -> -440 | J3932: =IF(I3932="","",ABS(I3932)) -> 440 | K3932: =IF(S3932="","",0) -> 0 | L3932: =IF(J3932="","",IF(AND(J3932>'Revenue Testing'!$E$9,K3932=0),1,0)) -> 0 | M3932: 0.83417225 | N3932: =IF(OR(A3932="",I3932=""),"",IF(COUNTIFS($A$2:$A$4500,A3932,$D$2:$D$4500,D3932,$I$2:$I$4500,I3932)>1,"Possible duplicate","")) | O3932: =IF(J3932="","",IF(AND(L3932=0,K3932=0),1,0)) -> 1 | P3932: =IF(L3932=1,J3932+ROW()/10^7,"") | Q3932: =IF(O3932=1,M3932,"") -> 0.83417225 | R3932: =IF(K3932=1,ROW(),"") | S3932: =IF(D3932="","",TRIM(D3932)) -> MISCELLANEOUS INCOME
A3933: GJAMS0021/25 | B3933: 46000 | C3933: =IF(S3933="","",IFERROR(IF(INDEX('Ledger Codes'!$C$6:$C$205,MATCH(S3933,'Ledger Codes'!$B$6:$B$205,0))="","",INDEX('Ledger Codes'!$C$6:$C$205,MATCH(S3933,'Ledger Codes'!$B$6:$B$205,0))),"")) -> 10083 | D3933: MISCELLANEOUS INCOME | F3933: EXCESS DETENTION PAID SAR 120- CSDIST002939 | G3933: 0 | H3933: 120 | I3933: =IF(AND(G3933="",H3933=""),"",N(G3933)-N(H3933)) -> -120 | J3933: =IF(I3933="","",ABS(I3933)) -> 120 | K3933: =IF(S3933="","",0) -> 0 | L3933: =IF(J3933="","",IF(AND(J3933>'Revenue Testing'!$E$9,K3933=0),1,0)) -> 0 | M3933: 0.4113673 | N3933: =IF(OR(A3933="",I3933=""),"",IF(COUNTIFS($A$2:$A$4500,A3933,$D$2:$D$4500,D3933,$I$2:$I$4500,I3933)>1,"Possible duplicate","")) | O3933: =IF(J3933="","",IF(AND(L3933=0,K3933=0),1,0)) -> 1 | P3933: =IF(L3933=1,J3933+ROW()/10^7,"") | Q3933: =IF(O3933=1,M3933,"") -> 0.4113673 | R3933: =IF(K3933=1,ROW(),"") | S3933: =IF(D3933="","",TRIM(D3933)) -> MISCELLANEOUS INCOME
A3934: DNAMS0008/25 | B3934: 46021 | C3934: =IF(S3934="","",IFERROR(IF(INDEX('Ledger Codes'!$C$6:$C$205,MATCH(S3934,'Ledger Codes'!$B$6:$B$205,0))="","",INDEX('Ledger Codes'!$C$6:$C$205,MATCH(S3934,'Ledger Codes'!$B$6:$B$205,0))),"")) -> 10083 | D3934: MISCELLANEOUS INCOME | E3934: 4365 | F3934: DEBIT NOTE AS AGREED WITH FREIGHT WORLD AGAINST INV 4365 | G3934: 0 | H3934: 270 | I3934: =IF(AND(G3934="",H3934=""),"",N(G3934)-N(H3934)) -> -270 | J3934: =IF(I3934="","",ABS(I3934)) -> 270 | K3934: =IF(S3934="","",0) -> 0 | L3934: =IF(J3934="","",IF(AND(J3934>'Revenue Testing'!$E$9,K3934=0),1,0)) -> 0 | M3934: 0.64076685 | N3934: =IF(OR(A3934="",I3934=""),"",IF(COUNTIFS($A$2:$A$4500,A3934,$D$2:$D$4500,D3934,$I$2:$I$4500,I3934)>1,"Possible duplicate","")) | O3934: =IF(J3934="","",IF(AND(L3934=0,K3934=0),1,0)) -> 1 | P3934: =IF(L3934=1,J3934+ROW()/10^7,"") | Q3934: =IF(O3934=1,M3934,"") -> 0.64076685 | R3934: =IF(K3934=1,ROW(),"") | S3934: =IF(D3934="","",TRIM(D3934)) -> MISCELLANEOUS INCOME
A3935: PJAMS0046/25 | B3935: 45963 | C3935: =IF(S3935="","",IFERROR(IF(INDEX('Ledger Codes'!$C$6:$C$205,MATCH(S3935,'Ledger Codes'!$B$6:$B$205,0))="","",INDEX('Ledger Codes'!$C$6:$C$205,MATCH(S3935,'Ledger Codes'!$B$6:$B$205,0))),"")) -> 10065 | D3935: TRANSPORTATION CHARGES | E3935: 3574 | F3935: PJ Ref:AMSLAP0018/25 ; INV- 3574 CSTAR- TRAMSPORTATION CHGS- SAR 270 X 7 TRIPS , SAR 135 X 1 TRIP- 20DV & SAR 270 X 29 TRIPS 40HC & FASAH APPOINTEMNT CHGS | G3935: 2025 | H3935: 0 | I3935: =IF(AND(G3935="",H3935=""),"",N(G3935)-N(H3935)) -> 2025 | J3935: =IF(I3935="","",ABS(I3935)) -> 2025 | K3935: =IF(S3935="","",0) -> 0 | L3935: =IF(J3935="","",IF(AND(J3935>'Revenue Testing'!$E$9,K3935=0),1,0)) -> 0 | M3935: 0.34241209 | N3935: =IF(OR(A3935="",I3935=""),"",IF(COUNTIFS($A$2:$A$4500,A3935,$D$2:$D$4500,D3935,$I$2:$I$4500,I3935)>1,"Possible duplicate","")) | O3935: =IF(J3935="","",IF(AND(L3935=0,K3935=0),1,0)) -> 1 | P3935: =IF(L3935=1,J3935+ROW()/10^7,"") | Q3935: =IF(O3935=1,M3935,"") -> 0.34241209 | R3935: =IF(K3935=1,ROW(),"") | S3935: =IF(D3935="","",TRIM(D3935)) -> TRANSPORTATION CHARGES
A3936: PJAMS0046/25 | B3936: 45963 | C3936: =IF(S3936="","",IFERROR(IF(INDEX('Ledger Codes'!$C$6:$C$205,MATCH(S3936,'Ledger Codes'!$B$6:$B$205,0))="","",INDEX('Ledger Codes'!$C$6:$C$205,MATCH(S3936,'Ledger Codes'!$B$6:$B$205,0))),"")) -> 10065 | D3936: TRANSPORTATION CHARGES | E3936: 3574 | F3936: PJ Ref:AMSLAP0018/25 ; INV- 3574 CSTAR- TRAMSPORTATION CHGS- SAR 270 X 7 TRIPS , SAR 135 X 1 TRIP- 20DV & SAR 270 X 29 TRIPS 40HC & FASAH APPOINTEMNT CHGS | G3936: 7830 | H3936: 0 | I3936: =IF(AND(G3936="",H3936=""),"",N(G3936)-N(H3936)) -> 7830 | J3936: =IF(I3936="","",ABS(I3936)) -> 7830 | K3936: =IF(S3936="","",0) -> 0 | L3936: =IF(J3936="","",IF(AND(J3936>'Revenue Testing'!$E$9,K3936=0),1,0)) -> 1 | M3936: 0.038374993 | N3936: =IF(OR(A3936="",I3936=""),"",IF(COUNTIFS($A$2:$A$4500,A3936,$D$2:$D$4500,D3936,$I$2:$I$4500,I3936)>1,"Possible duplicate","")) | O3936: =IF(J3936="","",IF(AND(L3936=0,K3936=0),1,0)) -> 0 | P3936: =IF(L3936=1,J3936+ROW()/10^7,"") -> 7830.0004 | Q3936: =IF(O3936=1,M3936,"") | R3936: =IF(K3936=1,ROW(),"") | S3936: =IF(D3936="","",TRIM(D3936)) -> TRANSPORTATION CHARGES
